https://apod.nasa.gov/apod/ap211025.html
https://apod.nasa.gov/apod/ap220114.html
https://apod.nasa.gov/apod/ap211012.html
https://apod.nasa.gov/apod/ap211203.html
https://apod.nasa.gov/apod/ap211018.html
https://apod.nasa.gov/apod/ap211109.html
https://apod.nasa.gov/apod/ap211120.html
https://apod.nasa.gov/apod/ap211201.html
https://apod.nasa.gov/apod/ap211123.html
https://apod.nasa.gov/apod/ap211009.html
https://apod.nasa.gov/apod/ap211221.html
https://apod.nasa.gov/apod/ap220103.html
https://apod.nasa.gov/apod/ap211113.html
https://apod.nasa.gov/apod/ap211013.html
https://apod.nasa.gov/apod/ap211025.html
https://apod.nasa.gov/apod/ap211124.html
https://apod.nasa.gov/apod/ap211018.html
https://apod.nasa.gov/apod/ap220115.html
https://apod.nasa.gov/apod/ap211201.html
https://apod.nasa.gov/apod/ap211012.html
https://apod.nasa.gov/apod/ap211022.html
https://apod.nasa.gov/apod/ap211021.html
https://apod.nasa.gov/apod/ap211122.html
https://apod.nasa.gov/apod/ap211102.html
https://apod.nasa.gov/apod/ap211023.html
https://apod.nasa.gov/apod/ap211226.html
https://apod.nasa.gov/apod/ap211213.html
https://apod.nasa.gov/apod/ap211119.html
https://apod.nasa.gov/apod/ap211122.html
https://apod.nasa.gov/apod/ap211207.html
https://apod.nasa.gov/apod/ap211124.html
https://apod.nasa.gov/apod/ap211031.html
https://apod.nasa.gov/apod/ap211125.html
https://apod.nasa.gov/apod/ap211103.html
https://apod.nasa.gov/apod/ap220101.html
https://apod.nasa.gov/apod/ap220101.html
https://apod.nasa.gov/apod/ap211225.html
https://apod.nasa.gov/apod/ap211018.html
https://apod.nasa.gov/apod/ap211028.html
https://apod.nasa.gov/apod/ap211023.html
https://apod.nasa.gov/apod/ap211019.html
https://apod.nasa.gov/apod/ap211125.html
https://apod.nasa.gov/apod/ap220104.html
https://apod.nasa.gov/apod/ap211109.html
https://apod.nasa.gov/apod/ap211031.html
https://apod.nasa.gov/apod/ap211019.html
https://apod.nasa.gov/apod/ap211216.html
https://apod.nasa.gov/apod/ap211226.html
https://apod.nasa.gov/apod/ap211120.html
https://apod.nasa.gov/apod/ap211106.html
https://apod.nasa.gov/apod/ap211009.html
https://apod.nasa.gov/apod/ap211107.html
https://apod.nasa.gov/apod/ap211029.html
https://apod.nasa.gov/apod/ap211229.html
https://apod.nasa.gov/apod/ap211210.html
https://apod.nasa.gov/apod/ap211113.html
https://apod.nasa.gov/apod/ap211206.html
https://apod.nasa.gov/apod/ap211107.html
https://apod.nasa.gov/apod/ap211101.html
https://apod.nasa.gov/apod/ap211222.html
https://apod.nasa.gov/apod/ap211106.html
https://apod.nasa.gov/apod/ap211028.html
https://apod.nasa.gov/apod/ap211011.html
('https://apod.nasa.gov/apod/ap220107.html', '220107')
Traceback (most recent call last):
  File "/Users/jacobl/cron_jobs/scripts/soupv2.py", line 48, in find_image
    img_url = img_tag.get('src')
AttributeError: 'NoneType' object has no attribute 'get'

During handling of the above exception, another exception occurred:

Traceback (most recent call last):
  File "/Users/jacobl/cron_jobs/scripts/soupv2.py", line 103, in <module>
    main()
  File "/Users/jacobl/cron_jobs/scripts/soupv2.py", line 96, in main
    img_url,description = find_image(site)
  File "/Users/jacobl/cron_jobs/scripts/soupv2.py", line 53, in find_image
    find_image(site)
  File "/Users/jacobl/cron_jobs/scripts/soupv2.py", line 45, in find_image
    soup = BeautifulSoup(requests.get(site).text, 'html.parser')
  File "/usr/local/lib/python3.9/site-packages/requests/api.py", line 76, in get
    return request('get', url, params=params, **kwargs)
  File "/usr/local/lib/python3.9/site-packages/requests/api.py", line 61, in request
    return session.request(method=method, url=url, **kwargs)
  File "/usr/local/lib/python3.9/site-packages/requests/sessions.py", line 530, in request
    resp = self.send(prep, **send_kwargs)
  File "/usr/local/lib/python3.9/site-packages/requests/sessions.py", line 637, in send
    adapter = self.get_adapter(url=request.url)
  File "/usr/local/lib/python3.9/site-packages/requests/sessions.py", line 730, in get_adapter
    raise InvalidSchema("No connection adapters were found for {!r}".format(url))
requests.exceptions.InvalidSchema: No connection adapters were found for "('https://apod.nasa.gov/apod/ap220107.html', '220107')"
https://apod.nasa.gov/apod/ap220113.html
https://apod.nasa.gov/apod/ap211109.html
https://apod.nasa.gov/apod/ap211123.html
https://apod.nasa.gov/apod/ap211110.html
('https://apod.nasa.gov/apod/ap220115.html', '220115')
Traceback (most recent call last):
  File "/Users/jacobl/cron_jobs/scripts/soupv2.py", line 48, in find_image
    img_url = img_tag.get('src')
AttributeError: 'NoneType' object has no attribute 'get'

During handling of the above exception, another exception occurred:

Traceback (most recent call last):
  File "/Users/jacobl/cron_jobs/scripts/soupv2.py", line 103, in <module>
    main()
  File "/Users/jacobl/cron_jobs/scripts/soupv2.py", line 96, in main
    img_url,description = find_image(site)
  File "/Users/jacobl/cron_jobs/scripts/soupv2.py", line 53, in find_image
    find_image(site)
  File "/Users/jacobl/cron_jobs/scripts/soupv2.py", line 45, in find_image
    soup = BeautifulSoup(requests.get(site).text, 'html.parser')
  File "/usr/local/lib/python3.9/site-packages/requests/api.py", line 76, in get
    return request('get', url, params=params, **kwargs)
  File "/usr/local/lib/python3.9/site-packages/requests/api.py", line 61, in request
    return session.request(method=method, url=url, **kwargs)
  File "/usr/local/lib/python3.9/site-packages/requests/sessions.py", line 530, in request
    resp = self.send(prep, **send_kwargs)
  File "/usr/local/lib/python3.9/site-packages/requests/sessions.py", line 637, in send
    adapter = self.get_adapter(url=request.url)
  File "/usr/local/lib/python3.9/site-packages/requests/sessions.py", line 730, in get_adapter
    raise InvalidSchema("No connection adapters were found for {!r}".format(url))
requests.exceptions.InvalidSchema: No connection adapters were found for "('https://apod.nasa.gov/apod/ap220115.html', '220115')"
rm: /Users/jacobl/wallpaper/*_up.jpg: No such file or directory
https://apod.nasa.gov/apod/ap211223.html
https://apod.nasa.gov/apod/ap220105.html
https://apod.nasa.gov/apod/ap211016.html
https://apod.nasa.gov/apod/ap201017.html
https://apod.nasa.gov/apod/ap210117.html
https://apod.nasa.gov/apod/ap201028.html
https://apod.nasa.gov/apod/ap201113.html
https://apod.nasa.gov/apod/ap210603.html
https://apod.nasa.gov/apod/ap210314.html
https://apod.nasa.gov/apod/ap211216.html
https://apod.nasa.gov/apod/ap211013.html
https://apod.nasa.gov/apod/ap201115.html
https://apod.nasa.gov/apod/ap211229.html
https://apod.nasa.gov/apod/ap210317.html
https://apod.nasa.gov/apod/ap210412.html
https://apod.nasa.gov/apod/ap210826.html
https://apod.nasa.gov/apod/ap201019.html
('https://apod.nasa.gov/apod/ap211116.html', '211116')
Traceback (most recent call last):
  File "/Users/jacobl/cron_jobs/scripts/soupv2.py", line 48, in find_image
    img_url = img_tag.get('src')
AttributeError: 'NoneType' object has no attribute 'get'

During handling of the above exception, another exception occurred:

Traceback (most recent call last):
  File "/Users/jacobl/cron_jobs/scripts/soupv2.py", line 103, in <module>
    main()
  File "/Users/jacobl/cron_jobs/scripts/soupv2.py", line 96, in main
    img_url,description = find_image(site)
  File "/Users/jacobl/cron_jobs/scripts/soupv2.py", line 53, in find_image
    find_image(site)
  File "/Users/jacobl/cron_jobs/scripts/soupv2.py", line 45, in find_image
    soup = BeautifulSoup(requests.get(site).text, 'html.parser')
  File "/usr/local/lib/python3.9/site-packages/requests/api.py", line 76, in get
    return request('get', url, params=params, **kwargs)
  File "/usr/local/lib/python3.9/site-packages/requests/api.py", line 61, in request
    return session.request(method=method, url=url, **kwargs)
  File "/usr/local/lib/python3.9/site-packages/requests/sessions.py", line 530, in request
    resp = self.send(prep, **send_kwargs)
  File "/usr/local/lib/python3.9/site-packages/requests/sessions.py", line 637, in send
    adapter = self.get_adapter(url=request.url)
  File "/usr/local/lib/python3.9/site-packages/requests/sessions.py", line 730, in get_adapter
    raise InvalidSchema("No connection adapters were found for {!r}".format(url))
requests.exceptions.InvalidSchema: No connection adapters were found for "('https://apod.nasa.gov/apod/ap211116.html', '211116')"
https://apod.nasa.gov/apod/ap211008.html
https://apod.nasa.gov/apod/ap210819.html
https://apod.nasa.gov/apod/ap210919.html
https://apod.nasa.gov/apod/ap210214.html
https://apod.nasa.gov/apod/ap210910.html
https://apod.nasa.gov/apod/ap211106.html
https://apod.nasa.gov/apod/ap210301.html
https://apod.nasa.gov/apod/ap211020.html
https://apod.nasa.gov/apod/ap210702.html
https://apod.nasa.gov/apod/ap210320.html
https://apod.nasa.gov/apod/ap211120.html
https://apod.nasa.gov/apod/ap211009.html
https://apod.nasa.gov/apod/ap200927.html
https://apod.nasa.gov/apod/ap220113.html
https://apod.nasa.gov/apod/ap210318.html
https://apod.nasa.gov/apod/ap210213.html
https://apod.nasa.gov/apod/ap201104.html
https://apod.nasa.gov/apod/ap210913.html
https://apod.nasa.gov/apod/ap210404.html
https://apod.nasa.gov/apod/ap210412.html
https://apod.nasa.gov/apod/ap210605.html
https://apod.nasa.gov/apod/ap210830.html
https://apod.nasa.gov/apod/ap210928.html
('https://apod.nasa.gov/apod/ap200925.html', '200925')
Traceback (most recent call last):
  File "/Users/jacobl/cron_jobs/scripts/soupv2.py", line 48, in find_image
    img_url = img_tag.get('src')
AttributeError: 'NoneType' object has no attribute 'get'

During handling of the above exception, another exception occurred:

Traceback (most recent call last):
  File "/Users/jacobl/cron_jobs/scripts/soupv2.py", line 103, in <module>
    main()
  File "/Users/jacobl/cron_jobs/scripts/soupv2.py", line 96, in main
    img_url,description = find_image(site)
  File "/Users/jacobl/cron_jobs/scripts/soupv2.py", line 53, in find_image
    find_image(site)
  File "/Users/jacobl/cron_jobs/scripts/soupv2.py", line 45, in find_image
    soup = BeautifulSoup(requests.get(site).text, 'html.parser')
  File "/usr/local/lib/python3.9/site-packages/requests/api.py", line 76, in get
    return request('get', url, params=params, **kwargs)
  File "/usr/local/lib/python3.9/site-packages/requests/api.py", line 61, in request
    return session.request(method=method, url=url, **kwargs)
  File "/usr/local/lib/python3.9/site-packages/requests/sessions.py", line 530, in request
    resp = self.send(prep, **send_kwargs)
  File "/usr/local/lib/python3.9/site-packages/requests/sessions.py", line 637, in send
    adapter = self.get_adapter(url=request.url)
  File "/usr/local/lib/python3.9/site-packages/requests/sessions.py", line 730, in get_adapter
    raise InvalidSchema("No connection adapters were found for {!r}".format(url))
requests.exceptions.InvalidSchema: No connection adapters were found for "('https://apod.nasa.gov/apod/ap200925.html', '200925')"
https://apod.nasa.gov/apod/ap210523.html
https://apod.nasa.gov/apod/ap210405.html
https://apod.nasa.gov/apod/ap210305.html
https://apod.nasa.gov/apod/ap201103.html
('https://apod.nasa.gov/apod/ap210523.html', '210523')
Traceback (most recent call last):
  File "/Users/jacobl/cron_jobs/scripts/soupv2.py", line 48, in find_image
    img_url = img_tag.get('src')
AttributeError: 'NoneType' object has no attribute 'get'

During handling of the above exception, another exception occurred:

Traceback (most recent call last):
  File "/Users/jacobl/cron_jobs/scripts/soupv2.py", line 103, in <module>
    main()
  File "/Users/jacobl/cron_jobs/scripts/soupv2.py", line 96, in main
    img_url,description = find_image(site)
  File "/Users/jacobl/cron_jobs/scripts/soupv2.py", line 53, in find_image
    find_image(site)
  File "/Users/jacobl/cron_jobs/scripts/soupv2.py", line 45, in find_image
    soup = BeautifulSoup(requests.get(site).text, 'html.parser')
  File "/usr/local/lib/python3.9/site-packages/requests/api.py", line 76, in get
    return request('get', url, params=params, **kwargs)
  File "/usr/local/lib/python3.9/site-packages/requests/api.py", line 61, in request
    return session.request(method=method, url=url, **kwargs)
  File "/usr/local/lib/python3.9/site-packages/requests/sessions.py", line 530, in request
    resp = self.send(prep, **send_kwargs)
  File "/usr/local/lib/python3.9/site-packages/requests/sessions.py", line 637, in send
    adapter = self.get_adapter(url=request.url)
  File "/usr/local/lib/python3.9/site-packages/requests/sessions.py", line 730, in get_adapter
    raise InvalidSchema("No connection adapters were found for {!r}".format(url))
requests.exceptions.InvalidSchema: No connection adapters were found for "('https://apod.nasa.gov/apod/ap210523.html', '210523')"
rm: /Users/jacobl/wallpaper/*_up.jpg: No such file or directory
https://apod.nasa.gov/apod/ap211216.html
https://apod.nasa.gov/apod/ap210601.html
https://apod.nasa.gov/apod/ap210728.html
https://apod.nasa.gov/apod/ap210509.html
https://apod.nasa.gov/apod/ap201025.html
https://apod.nasa.gov/apod/ap201224.html
https://apod.nasa.gov/apod/ap210829.html
https://apod.nasa.gov/apod/ap210920.html
https://apod.nasa.gov/apod/ap201020.html
https://apod.nasa.gov/apod/ap201118.html
https://apod.nasa.gov/apod/ap220109.html
https://apod.nasa.gov/apod/ap210726.html
https://apod.nasa.gov/apod/ap211211.html
https://apod.nasa.gov/apod/ap210501.html
https://apod.nasa.gov/apod/ap201213.html
https://apod.nasa.gov/apod/ap210629.html
https://apod.nasa.gov/apod/ap210328.html
https://apod.nasa.gov/apod/ap210331.html
https://apod.nasa.gov/apod/ap201005.html
https://apod.nasa.gov/apod/ap210217.html
https://apod.nasa.gov/apod/ap210922.html
('https://apod.nasa.gov/apod/ap211213.html', '211213')
Traceback (most recent call last):
  File "/Users/jacobl/cron_jobs/scripts/soupv2.py", line 48, in find_image
    img_url = img_tag.get('src')
AttributeError: 'NoneType' object has no attribute 'get'

During handling of the above exception, another exception occurred:

Traceback (most recent call last):
  File "/Users/jacobl/cron_jobs/scripts/soupv2.py", line 103, in <module>
    main()
  File "/Users/jacobl/cron_jobs/scripts/soupv2.py", line 96, in main
    img_url,description = find_image(site)
  File "/Users/jacobl/cron_jobs/scripts/soupv2.py", line 53, in find_image
    find_image(site)
  File "/Users/jacobl/cron_jobs/scripts/soupv2.py", line 45, in find_image
    soup = BeautifulSoup(requests.get(site).text, 'html.parser')
  File "/usr/local/lib/python3.9/site-packages/requests/api.py", line 76, in get
    return request('get', url, params=params, **kwargs)
  File "/usr/local/lib/python3.9/site-packages/requests/api.py", line 61, in request
    return session.request(method=method, url=url, **kwargs)
  File "/usr/local/lib/python3.9/site-packages/requests/sessions.py", line 530, in request
    resp = self.send(prep, **send_kwargs)
  File "/usr/local/lib/python3.9/site-packages/requests/sessions.py", line 637, in send
    adapter = self.get_adapter(url=request.url)
  File "/usr/local/lib/python3.9/site-packages/requests/sessions.py", line 730, in get_adapter
    raise InvalidSchema("No connection adapters were found for {!r}".format(url))
requests.exceptions.InvalidSchema: No connection adapters were found for "('https://apod.nasa.gov/apod/ap211213.html', '211213')"
https://apod.nasa.gov/apod/ap201220.html
https://apod.nasa.gov/apod/ap210417.html
https://apod.nasa.gov/apod/ap201014.html
https://apod.nasa.gov/apod/ap210705.html
https://apod.nasa.gov/apod/ap201009.html
https://apod.nasa.gov/apod/ap210819.html
https://apod.nasa.gov/apod/ap200916.html
https://apod.nasa.gov/apod/ap210713.html
('https://apod.nasa.gov/apod/ap211213.html', '211213')
Traceback (most recent call last):
  File "/Users/jacobl/cron_jobs/scripts/soupv2.py", line 48, in find_image
    img_url = img_tag.get('src')
AttributeError: 'NoneType' object has no attribute 'get'

During handling of the above exception, another exception occurred:

Traceback (most recent call last):
  File "/Users/jacobl/cron_jobs/scripts/soupv2.py", line 103, in <module>
    main()
  File "/Users/jacobl/cron_jobs/scripts/soupv2.py", line 96, in main
    img_url,description = find_image(site)
  File "/Users/jacobl/cron_jobs/scripts/soupv2.py", line 53, in find_image
    find_image(site)
  File "/Users/jacobl/cron_jobs/scripts/soupv2.py", line 45, in find_image
    soup = BeautifulSoup(requests.get(site).text, 'html.parser')
  File "/usr/local/lib/python3.9/site-packages/requests/api.py", line 76, in get
    return request('get', url, params=params, **kwargs)
  File "/usr/local/lib/python3.9/site-packages/requests/api.py", line 61, in request
    return session.request(method=method, url=url, **kwargs)
  File "/usr/local/lib/python3.9/site-packages/requests/sessions.py", line 530, in request
    resp = self.send(prep, **send_kwargs)
  File "/usr/local/lib/python3.9/site-packages/requests/sessions.py", line 637, in send
    adapter = self.get_adapter(url=request.url)
  File "/usr/local/lib/python3.9/site-packages/requests/sessions.py", line 730, in get_adapter
    raise InvalidSchema("No connection adapters were found for {!r}".format(url))
requests.exceptions.InvalidSchema: No connection adapters were found for "('https://apod.nasa.gov/apod/ap211213.html', '211213')"
https://apod.nasa.gov/apod/ap210413.html
https://apod.nasa.gov/apod/ap201130.html
https://apod.nasa.gov/apod/ap210919.html
https://apod.nasa.gov/apod/ap210407.html
https://apod.nasa.gov/apod/ap210710.html
https://apod.nasa.gov/apod/ap211109.html
https://apod.nasa.gov/apod/ap211221.html
https://apod.nasa.gov/apod/ap210929.html
('https://apod.nasa.gov/apod/ap211008.html', '211008')
Traceback (most recent call last):
  File "/Users/jacobl/cron_jobs/scripts/soupv2.py", line 48, in find_image
    img_url = img_tag.get('src')
AttributeError: 'NoneType' object has no attribute 'get'

During handling of the above exception, another exception occurred:

Traceback (most recent call last):
  File "/Users/jacobl/cron_jobs/scripts/soupv2.py", line 103, in <module>
    main()
  File "/Users/jacobl/cron_jobs/scripts/soupv2.py", line 96, in main
    img_url,description = find_image(site)
  File "/Users/jacobl/cron_jobs/scripts/soupv2.py", line 53, in find_image
    find_image(site)
  File "/Users/jacobl/cron_jobs/scripts/soupv2.py", line 45, in find_image
    soup = BeautifulSoup(requests.get(site).text, 'html.parser')
  File "/usr/local/lib/python3.9/site-packages/requests/api.py", line 76, in get
    return request('get', url, params=params, **kwargs)
  File "/usr/local/lib/python3.9/site-packages/requests/api.py", line 61, in request
    return session.request(method=method, url=url, **kwargs)
  File "/usr/local/lib/python3.9/site-packages/requests/sessions.py", line 530, in request
    resp = self.send(prep, **send_kwargs)
  File "/usr/local/lib/python3.9/site-packages/requests/sessions.py", line 637, in send
    adapter = self.get_adapter(url=request.url)
  File "/usr/local/lib/python3.9/site-packages/requests/sessions.py", line 730, in get_adapter
    raise InvalidSchema("No connection adapters were found for {!r}".format(url))
requests.exceptions.InvalidSchema: No connection adapters were found for "('https://apod.nasa.gov/apod/ap211008.html', '211008')"
https://apod.nasa.gov/apod/ap210314.html
https://apod.nasa.gov/apod/ap211122.html
https://apod.nasa.gov/apod/ap210421.html
https://apod.nasa.gov/apod/ap210409.html
https://apod.nasa.gov/apod/ap210305.html
https://apod.nasa.gov/apod/ap210104.html
('https://apod.nasa.gov/apod/ap211210.html', '211210')
Traceback (most recent call last):
  File "/Users/jacobl/cron_jobs/scripts/soupv2.py", line 48, in find_image
    img_url = img_tag.get('src')
AttributeError: 'NoneType' object has no attribute 'get'

During handling of the above exception, another exception occurred:

Traceback (most recent call last):
  File "/Users/jacobl/cron_jobs/scripts/soupv2.py", line 103, in <module>
    main()
  File "/Users/jacobl/cron_jobs/scripts/soupv2.py", line 96, in main
    img_url,description = find_image(site)
  File "/Users/jacobl/cron_jobs/scripts/soupv2.py", line 53, in find_image
    find_image(site)
  File "/Users/jacobl/cron_jobs/scripts/soupv2.py", line 45, in find_image
    soup = BeautifulSoup(requests.get(site).text, 'html.parser')
  File "/usr/local/lib/python3.9/site-packages/requests/api.py", line 76, in get
    return request('get', url, params=params, **kwargs)
  File "/usr/local/lib/python3.9/site-packages/requests/api.py", line 61, in request
    return session.request(method=method, url=url, **kwargs)
  File "/usr/local/lib/python3.9/site-packages/requests/sessions.py", line 530, in request
    resp = self.send(prep, **send_kwargs)
  File "/usr/local/lib/python3.9/site-packages/requests/sessions.py", line 637, in send
    adapter = self.get_adapter(url=request.url)
  File "/usr/local/lib/python3.9/site-packages/requests/sessions.py", line 730, in get_adapter
    raise InvalidSchema("No connection adapters were found for {!r}".format(url))
requests.exceptions.InvalidSchema: No connection adapters were found for "('https://apod.nasa.gov/apod/ap211210.html', '211210')"
https://apod.nasa.gov/apod/ap211216.html
https://apod.nasa.gov/apod/ap210729.html
https://apod.nasa.gov/apod/ap210105.html
https://apod.nasa.gov/apod/ap210220.html
https://apod.nasa.gov/apod/ap210329.html
https://apod.nasa.gov/apod/ap210215.html
('https://apod.nasa.gov/apod/ap210226.html', '210226')
Traceback (most recent call last):
  File "/Users/jacobl/cron_jobs/scripts/soupv2.py", line 48, in find_image
    img_url = img_tag.get('src')
AttributeError: 'NoneType' object has no attribute 'get'

During handling of the above exception, another exception occurred:

Traceback (most recent call last):
  File "/Users/jacobl/cron_jobs/scripts/soupv2.py", line 103, in <module>
    main()
  File "/Users/jacobl/cron_jobs/scripts/soupv2.py", line 96, in main
    img_url,description = find_image(site)
  File "/Users/jacobl/cron_jobs/scripts/soupv2.py", line 53, in find_image
    find_image(site)
  File "/Users/jacobl/cron_jobs/scripts/soupv2.py", line 45, in find_image
    soup = BeautifulSoup(requests.get(site).text, 'html.parser')
  File "/usr/local/lib/python3.9/site-packages/requests/api.py", line 76, in get
    return request('get', url, params=params, **kwargs)
  File "/usr/local/lib/python3.9/site-packages/requests/api.py", line 61, in request
    return session.request(method=method, url=url, **kwargs)
  File "/usr/local/lib/python3.9/site-packages/requests/sessions.py", line 530, in request
    resp = self.send(prep, **send_kwargs)
  File "/usr/local/lib/python3.9/site-packages/requests/sessions.py", line 637, in send
    adapter = self.get_adapter(url=request.url)
  File "/usr/local/lib/python3.9/site-packages/requests/sessions.py", line 730, in get_adapter
    raise InvalidSchema("No connection adapters were found for {!r}".format(url))
requests.exceptions.InvalidSchema: No connection adapters were found for "('https://apod.nasa.gov/apod/ap210226.html', '210226')"
https://apod.nasa.gov/apod/ap210314.html
https://apod.nasa.gov/apod/ap210116.html
https://apod.nasa.gov/apod/ap210607.html
https://apod.nasa.gov/apod/ap201216.html
('https://apod.nasa.gov/apod/ap211019.html', '211019')
Traceback (most recent call last):
  File "/Users/jacobl/cron_jobs/scripts/soupv2.py", line 48, in find_image
    img_url = img_tag.get('src')
AttributeError: 'NoneType' object has no attribute 'get'

During handling of the above exception, another exception occurred:

Traceback (most recent call last):
  File "/Users/jacobl/cron_jobs/scripts/soupv2.py", line 103, in <module>
    main()
  File "/Users/jacobl/cron_jobs/scripts/soupv2.py", line 96, in main
    img_url,description = find_image(site)
  File "/Users/jacobl/cron_jobs/scripts/soupv2.py", line 53, in find_image
    find_image(site)
  File "/Users/jacobl/cron_jobs/scripts/soupv2.py", line 45, in find_image
    soup = BeautifulSoup(requests.get(site).text, 'html.parser')
  File "/usr/local/lib/python3.9/site-packages/requests/api.py", line 76, in get
    return request('get', url, params=params, **kwargs)
  File "/usr/local/lib/python3.9/site-packages/requests/api.py", line 61, in request
    return session.request(method=method, url=url, **kwargs)
  File "/usr/local/lib/python3.9/site-packages/requests/sessions.py", line 530, in request
    resp = self.send(prep, **send_kwargs)
  File "/usr/local/lib/python3.9/site-packages/requests/sessions.py", line 637, in send
    adapter = self.get_adapter(url=request.url)
  File "/usr/local/lib/python3.9/site-packages/requests/sessions.py", line 730, in get_adapter
    raise InvalidSchema("No connection adapters were found for {!r}".format(url))
requests.exceptions.InvalidSchema: No connection adapters were found for "('https://apod.nasa.gov/apod/ap211019.html', '211019')"
rm: /Users/jacobl/wallpaper/*_up.jpg: No such file or directory
https://apod.nasa.gov/apod/ap210827.html
https://apod.nasa.gov/apod/ap211101.html
https://apod.nasa.gov/apod/ap210325.html
https://apod.nasa.gov/apod/ap211122.html
https://apod.nasa.gov/apod/ap211101.html
https://apod.nasa.gov/apod/ap220109.html
https://apod.nasa.gov/apod/ap210606.html
https://apod.nasa.gov/apod/ap211214.html
https://apod.nasa.gov/apod/ap210619.html
https://apod.nasa.gov/apod/ap211023.html
https://apod.nasa.gov/apod/ap201206.html
https://apod.nasa.gov/apod/ap200912.html
('https://apod.nasa.gov/apod/ap210814.html', '210814')
Traceback (most recent call last):
  File "/Users/jacobl/cron_jobs/scripts/soupv2.py", line 48, in find_image
    img_url = img_tag.get('src')
AttributeError: 'NoneType' object has no attribute 'get'

During handling of the above exception, another exception occurred:

Traceback (most recent call last):
  File "/Users/jacobl/cron_jobs/scripts/soupv2.py", line 103, in <module>
    main()
  File "/Users/jacobl/cron_jobs/scripts/soupv2.py", line 96, in main
    img_url,description = find_image(site)
  File "/Users/jacobl/cron_jobs/scripts/soupv2.py", line 53, in find_image
    find_image(site)
  File "/Users/jacobl/cron_jobs/scripts/soupv2.py", line 45, in find_image
    soup = BeautifulSoup(requests.get(site).text, 'html.parser')
  File "/usr/local/lib/python3.9/site-packages/requests/api.py", line 76, in get
    return request('get', url, params=params, **kwargs)
  File "/usr/local/lib/python3.9/site-packages/requests/api.py", line 61, in request
    return session.request(method=method, url=url, **kwargs)
  File "/usr/local/lib/python3.9/site-packages/requests/sessions.py", line 530, in request
    resp = self.send(prep, **send_kwargs)
  File "/usr/local/lib/python3.9/site-packages/requests/sessions.py", line 637, in send
    adapter = self.get_adapter(url=request.url)
  File "/usr/local/lib/python3.9/site-packages/requests/sessions.py", line 730, in get_adapter
    raise InvalidSchema("No connection adapters were found for {!r}".format(url))
requests.exceptions.InvalidSchema: No connection adapters were found for "('https://apod.nasa.gov/apod/ap210814.html', '210814')"
https://apod.nasa.gov/apod/ap210911.html
https://apod.nasa.gov/apod/ap211025.html
https://apod.nasa.gov/apod/ap210412.html
https://apod.nasa.gov/apod/ap201116.html
https://apod.nasa.gov/apod/ap210721.html
https://apod.nasa.gov/apod/ap210416.html
('https://apod.nasa.gov/apod/ap211125.html', '211125')
Traceback (most recent call last):
  File "/Users/jacobl/cron_jobs/scripts/soupv2.py", line 48, in find_image
    img_url = img_tag.get('src')
AttributeError: 'NoneType' object has no attribute 'get'

During handling of the above exception, another exception occurred:

Traceback (most recent call last):
  File "/Users/jacobl/cron_jobs/scripts/soupv2.py", line 103, in <module>
    main()
  File "/Users/jacobl/cron_jobs/scripts/soupv2.py", line 96, in main
    img_url,description = find_image(site)
  File "/Users/jacobl/cron_jobs/scripts/soupv2.py", line 53, in find_image
    find_image(site)
  File "/Users/jacobl/cron_jobs/scripts/soupv2.py", line 45, in find_image
    soup = BeautifulSoup(requests.get(site).text, 'html.parser')
  File "/usr/local/lib/python3.9/site-packages/requests/api.py", line 76, in get
    return request('get', url, params=params, **kwargs)
  File "/usr/local/lib/python3.9/site-packages/requests/api.py", line 61, in request
    return session.request(method=method, url=url, **kwargs)
  File "/usr/local/lib/python3.9/site-packages/requests/sessions.py", line 530, in request
    resp = self.send(prep, **send_kwargs)
  File "/usr/local/lib/python3.9/site-packages/requests/sessions.py", line 637, in send
    adapter = self.get_adapter(url=request.url)
  File "/usr/local/lib/python3.9/site-packages/requests/sessions.py", line 730, in get_adapter
    raise InvalidSchema("No connection adapters were found for {!r}".format(url))
requests.exceptions.InvalidSchema: No connection adapters were found for "('https://apod.nasa.gov/apod/ap211125.html', '211125')"
https://apod.nasa.gov/apod/ap210323.html
https://apod.nasa.gov/apod/ap211009.html
https://apod.nasa.gov/apod/ap210721.html
https://apod.nasa.gov/apod/ap210730.html
https://apod.nasa.gov/apod/ap210306.html
https://apod.nasa.gov/apod/ap201020.html
https://apod.nasa.gov/apod/ap210916.html
https://apod.nasa.gov/apod/ap210413.html
https://apod.nasa.gov/apod/ap210422.html
https://apod.nasa.gov/apod/ap201229.html
('https://apod.nasa.gov/apod/ap201115.html', '201115')
Traceback (most recent call last):
  File "/Users/jacobl/cron_jobs/scripts/soupv2.py", line 48, in find_image
    img_url = img_tag.get('src')
AttributeError: 'NoneType' object has no attribute 'get'

During handling of the above exception, another exception occurred:

Traceback (most recent call last):
  File "/Users/jacobl/cron_jobs/scripts/soupv2.py", line 103, in <module>
    main()
  File "/Users/jacobl/cron_jobs/scripts/soupv2.py", line 96, in main
    img_url,description = find_image(site)
  File "/Users/jacobl/cron_jobs/scripts/soupv2.py", line 53, in find_image
    find_image(site)
  File "/Users/jacobl/cron_jobs/scripts/soupv2.py", line 45, in find_image
    soup = BeautifulSoup(requests.get(site).text, 'html.parser')
  File "/usr/local/lib/python3.9/site-packages/requests/api.py", line 76, in get
    return request('get', url, params=params, **kwargs)
  File "/usr/local/lib/python3.9/site-packages/requests/api.py", line 61, in request
    return session.request(method=method, url=url, **kwargs)
  File "/usr/local/lib/python3.9/site-packages/requests/sessions.py", line 530, in request
    resp = self.send(prep, **send_kwargs)
  File "/usr/local/lib/python3.9/site-packages/requests/sessions.py", line 637, in send
    adapter = self.get_adapter(url=request.url)
  File "/usr/local/lib/python3.9/site-packages/requests/sessions.py", line 730, in get_adapter
    raise InvalidSchema("No connection adapters were found for {!r}".format(url))
requests.exceptions.InvalidSchema: No connection adapters were found for "('https://apod.nasa.gov/apod/ap201115.html', '201115')"
rm: /Users/jacobl/wallpaper/*_up.jpg: No such file or directory
https://apod.nasa.gov/apod/ap210721.html
https://apod.nasa.gov/apod/ap210721.html
https://apod.nasa.gov/apod/ap210905.html
('https://apod.nasa.gov/apod/ap220113.html', '220113')
Traceback (most recent call last):
  File "/Users/jacobl/cron_jobs/scripts/soupv2.py", line 48, in find_image
    img_url = img_tag.get('src')
AttributeError: 'NoneType' object has no attribute 'get'

During handling of the above exception, another exception occurred:

Traceback (most recent call last):
  File "/Users/jacobl/cron_jobs/scripts/soupv2.py", line 103, in <module>
    main()
  File "/Users/jacobl/cron_jobs/scripts/soupv2.py", line 96, in main
    img_url,description = find_image(site)
  File "/Users/jacobl/cron_jobs/scripts/soupv2.py", line 53, in find_image
    find_image(site)
  File "/Users/jacobl/cron_jobs/scripts/soupv2.py", line 45, in find_image
    soup = BeautifulSoup(requests.get(site).text, 'html.parser')
  File "/usr/local/lib/python3.9/site-packages/requests/api.py", line 76, in get
    return request('get', url, params=params, **kwargs)
  File "/usr/local/lib/python3.9/site-packages/requests/api.py", line 61, in request
    return session.request(method=method, url=url, **kwargs)
  File "/usr/local/lib/python3.9/site-packages/requests/sessions.py", line 530, in request
    resp = self.send(prep, **send_kwargs)
  File "/usr/local/lib/python3.9/site-packages/requests/sessions.py", line 637, in send
    adapter = self.get_adapter(url=request.url)
  File "/usr/local/lib/python3.9/site-packages/requests/sessions.py", line 730, in get_adapter
    raise InvalidSchema("No connection adapters were found for {!r}".format(url))
requests.exceptions.InvalidSchema: No connection adapters were found for "('https://apod.nasa.gov/apod/ap220113.html', '220113')"
https://apod.nasa.gov/apod/ap211009.html
https://apod.nasa.gov/apod/ap201015.html
https://apod.nasa.gov/apod/ap220103.html
https://apod.nasa.gov/apod/ap201019.html
('https://apod.nasa.gov/apod/ap210303.html', '210303')
Traceback (most recent call last):
  File "/Users/jacobl/cron_jobs/scripts/soupv2.py", line 48, in find_image
    img_url = img_tag.get('src')
AttributeError: 'NoneType' object has no attribute 'get'

During handling of the above exception, another exception occurred:

Traceback (most recent call last):
  File "/Users/jacobl/cron_jobs/scripts/soupv2.py", line 103, in <module>
    main()
  File "/Users/jacobl/cron_jobs/scripts/soupv2.py", line 96, in main
    img_url,description = find_image(site)
  File "/Users/jacobl/cron_jobs/scripts/soupv2.py", line 53, in find_image
    find_image(site)
  File "/Users/jacobl/cron_jobs/scripts/soupv2.py", line 45, in find_image
    soup = BeautifulSoup(requests.get(site).text, 'html.parser')
  File "/usr/local/lib/python3.9/site-packages/requests/api.py", line 76, in get
    return request('get', url, params=params, **kwargs)
  File "/usr/local/lib/python3.9/site-packages/requests/api.py", line 61, in request
    return session.request(method=method, url=url, **kwargs)
  File "/usr/local/lib/python3.9/site-packages/requests/sessions.py", line 530, in request
    resp = self.send(prep, **send_kwargs)
  File "/usr/local/lib/python3.9/site-packages/requests/sessions.py", line 637, in send
    adapter = self.get_adapter(url=request.url)
  File "/usr/local/lib/python3.9/site-packages/requests/sessions.py", line 730, in get_adapter
    raise InvalidSchema("No connection adapters were found for {!r}".format(url))
requests.exceptions.InvalidSchema: No connection adapters were found for "('https://apod.nasa.gov/apod/ap210303.html', '210303')"
rm: /Users/jacobl/wallpaper/*_up.jpg: No such file or directory
https://apod.nasa.gov/apod/ap211118.html
https://apod.nasa.gov/apod/ap211023.html
https://apod.nasa.gov/apod/ap201114.html
https://apod.nasa.gov/apod/ap210917.html
('https://apod.nasa.gov/apod/ap210225.html', '210225')
Traceback (most recent call last):
  File "/Users/jacobl/cron_jobs/scripts/soupv2.py", line 48, in find_image
    img_url = img_tag.get('src')
AttributeError: 'NoneType' object has no attribute 'get'

During handling of the above exception, another exception occurred:

Traceback (most recent call last):
  File "/Users/jacobl/cron_jobs/scripts/soupv2.py", line 103, in <module>
    main()
  File "/Users/jacobl/cron_jobs/scripts/soupv2.py", line 96, in main
    img_url,description = find_image(site)
  File "/Users/jacobl/cron_jobs/scripts/soupv2.py", line 53, in find_image
    find_image(site)
  File "/Users/jacobl/cron_jobs/scripts/soupv2.py", line 45, in find_image
    soup = BeautifulSoup(requests.get(site).text, 'html.parser')
  File "/usr/local/lib/python3.9/site-packages/requests/api.py", line 76, in get
    return request('get', url, params=params, **kwargs)
  File "/usr/local/lib/python3.9/site-packages/requests/api.py", line 61, in request
    return session.request(method=method, url=url, **kwargs)
  File "/usr/local/lib/python3.9/site-packages/requests/sessions.py", line 530, in request
    resp = self.send(prep, **send_kwargs)
  File "/usr/local/lib/python3.9/site-packages/requests/sessions.py", line 637, in send
    adapter = self.get_adapter(url=request.url)
  File "/usr/local/lib/python3.9/site-packages/requests/sessions.py", line 730, in get_adapter
    raise InvalidSchema("No connection adapters were found for {!r}".format(url))
requests.exceptions.InvalidSchema: No connection adapters were found for "('https://apod.nasa.gov/apod/ap210225.html', '210225')"
rm: /Users/jacobl/wallpaper/*_up.jpg: No such file or directory
https://apod.nasa.gov/apod/ap210106.html
https://apod.nasa.gov/apod/ap200925.html
https://apod.nasa.gov/apod/ap210902.html
https://apod.nasa.gov/apod/ap210920.html
https://apod.nasa.gov/apod/ap211013.html
https://apod.nasa.gov/apod/ap211106.html
https://apod.nasa.gov/apod/ap210502.html
https://apod.nasa.gov/apod/ap211202.html
https://apod.nasa.gov/apod/ap220107.html
https://apod.nasa.gov/apod/ap211225.html
https://apod.nasa.gov/apod/ap210107.html
https://apod.nasa.gov/apod/ap210113.html
https://apod.nasa.gov/apod/ap201211.html
https://apod.nasa.gov/apod/ap210922.html
('https://apod.nasa.gov/apod/ap220111.html', '220111')
Traceback (most recent call last):
  File "/Users/jacobl/cron_jobs/scripts/soupv2.py", line 48, in find_image
    img_url = img_tag.get('src')
AttributeError: 'NoneType' object has no attribute 'get'

During handling of the above exception, another exception occurred:

Traceback (most recent call last):
  File "/Users/jacobl/cron_jobs/scripts/soupv2.py", line 103, in <module>
    main()
  File "/Users/jacobl/cron_jobs/scripts/soupv2.py", line 96, in main
    img_url,description = find_image(site)
  File "/Users/jacobl/cron_jobs/scripts/soupv2.py", line 53, in find_image
    find_image(site)
  File "/Users/jacobl/cron_jobs/scripts/soupv2.py", line 45, in find_image
    soup = BeautifulSoup(requests.get(site).text, 'html.parser')
  File "/usr/local/lib/python3.9/site-packages/requests/api.py", line 76, in get
    return request('get', url, params=params, **kwargs)
  File "/usr/local/lib/python3.9/site-packages/requests/api.py", line 61, in request
    return session.request(method=method, url=url, **kwargs)
  File "/usr/local/lib/python3.9/site-packages/requests/sessions.py", line 530, in request
    resp = self.send(prep, **send_kwargs)
  File "/usr/local/lib/python3.9/site-packages/requests/sessions.py", line 637, in send
    adapter = self.get_adapter(url=request.url)
  File "/usr/local/lib/python3.9/site-packages/requests/sessions.py", line 730, in get_adapter
    raise InvalidSchema("No connection adapters were found for {!r}".format(url))
requests.exceptions.InvalidSchema: No connection adapters were found for "('https://apod.nasa.gov/apod/ap220111.html', '220111')"
https://apod.nasa.gov/apod/ap210505.html
https://apod.nasa.gov/apod/ap210423.html
('https://apod.nasa.gov/apod/ap210517.html', '210517')
Traceback (most recent call last):
  File "/Users/jacobl/cron_jobs/scripts/soupv2.py", line 48, in find_image
    img_url = img_tag.get('src')
AttributeError: 'NoneType' object has no attribute 'get'

During handling of the above exception, another exception occurred:

Traceback (most recent call last):
  File "/Users/jacobl/cron_jobs/scripts/soupv2.py", line 103, in <module>
    main()
  File "/Users/jacobl/cron_jobs/scripts/soupv2.py", line 96, in main
    img_url,description = find_image(site)
  File "/Users/jacobl/cron_jobs/scripts/soupv2.py", line 53, in find_image
    find_image(site)
  File "/Users/jacobl/cron_jobs/scripts/soupv2.py", line 45, in find_image
    soup = BeautifulSoup(requests.get(site).text, 'html.parser')
  File "/usr/local/lib/python3.9/site-packages/requests/api.py", line 76, in get
    return request('get', url, params=params, **kwargs)
  File "/usr/local/lib/python3.9/site-packages/requests/api.py", line 61, in request
    return session.request(method=method, url=url, **kwargs)
  File "/usr/local/lib/python3.9/site-packages/requests/sessions.py", line 530, in request
    resp = self.send(prep, **send_kwargs)
  File "/usr/local/lib/python3.9/site-packages/requests/sessions.py", line 637, in send
    adapter = self.get_adapter(url=request.url)
  File "/usr/local/lib/python3.9/site-packages/requests/sessions.py", line 730, in get_adapter
    raise InvalidSchema("No connection adapters were found for {!r}".format(url))
requests.exceptions.InvalidSchema: No connection adapters were found for "('https://apod.nasa.gov/apod/ap210517.html', '210517')"
https://apod.nasa.gov/apod/ap210404.html
https://apod.nasa.gov/apod/ap201230.html
('https://apod.nasa.gov/apod/ap210101.html', '210101')
Traceback (most recent call last):
  File "/Users/jacobl/cron_jobs/scripts/soupv2.py", line 48, in find_image
    img_url = img_tag.get('src')
AttributeError: 'NoneType' object has no attribute 'get'

During handling of the above exception, another exception occurred:

Traceback (most recent call last):
  File "/Users/jacobl/cron_jobs/scripts/soupv2.py", line 103, in <module>
    main()
  File "/Users/jacobl/cron_jobs/scripts/soupv2.py", line 96, in main
    img_url,description = find_image(site)
  File "/Users/jacobl/cron_jobs/scripts/soupv2.py", line 53, in find_image
    find_image(site)
  File "/Users/jacobl/cron_jobs/scripts/soupv2.py", line 45, in find_image
    soup = BeautifulSoup(requests.get(site).text, 'html.parser')
  File "/usr/local/lib/python3.9/site-packages/requests/api.py", line 76, in get
    return request('get', url, params=params, **kwargs)
  File "/usr/local/lib/python3.9/site-packages/requests/api.py", line 61, in request
    return session.request(method=method, url=url, **kwargs)
  File "/usr/local/lib/python3.9/site-packages/requests/sessions.py", line 530, in request
    resp = self.send(prep, **send_kwargs)
  File "/usr/local/lib/python3.9/site-packages/requests/sessions.py", line 637, in send
    adapter = self.get_adapter(url=request.url)
  File "/usr/local/lib/python3.9/site-packages/requests/sessions.py", line 730, in get_adapter
    raise InvalidSchema("No connection adapters were found for {!r}".format(url))
requests.exceptions.InvalidSchema: No connection adapters were found for "('https://apod.nasa.gov/apod/ap210101.html', '210101')"
https://apod.nasa.gov/apod/ap201220.html
https://apod.nasa.gov/apod/ap200913.html
https://apod.nasa.gov/apod/ap210219.html
https://apod.nasa.gov/apod/ap210308.html
https://apod.nasa.gov/apod/ap201118.html
https://apod.nasa.gov/apod/ap210225.html
https://apod.nasa.gov/apod/ap220116.html
https://apod.nasa.gov/apod/ap210118.html
https://apod.nasa.gov/apod/ap210221.html
https://apod.nasa.gov/apod/ap210430.html
https://apod.nasa.gov/apod/ap210415.html
https://apod.nasa.gov/apod/ap210607.html
https://apod.nasa.gov/apod/ap210130.html
https://apod.nasa.gov/apod/ap210102.html
https://apod.nasa.gov/apod/ap210806.html
https://apod.nasa.gov/apod/ap210509.html
https://apod.nasa.gov/apod/ap210901.html
https://apod.nasa.gov/apod/ap200906.html
https://apod.nasa.gov/apod/ap200921.html
https://apod.nasa.gov/apod/ap210131.html
https://apod.nasa.gov/apod/ap211120.html
https://apod.nasa.gov/apod/ap201210.html
https://apod.nasa.gov/apod/ap210826.html
https://apod.nasa.gov/apod/ap200907.html
https://apod.nasa.gov/apod/ap210722.html
https://apod.nasa.gov/apod/ap210504.html
https://apod.nasa.gov/apod/ap210210.html
https://apod.nasa.gov/apod/ap210918.html
https://apod.nasa.gov/apod/ap201029.html
https://apod.nasa.gov/apod/ap210410.html
https://apod.nasa.gov/apod/ap201221.html
https://apod.nasa.gov/apod/ap210613.html
('https://apod.nasa.gov/apod/ap201208.html', '201208')
Traceback (most recent call last):
  File "/Users/jacobl/cron_jobs/scripts/soupv2.py", line 48, in find_image
    img_url = img_tag.get('src')
AttributeError: 'NoneType' object has no attribute 'get'

During handling of the above exception, another exception occurred:

Traceback (most recent call last):
  File "/Users/jacobl/cron_jobs/scripts/soupv2.py", line 103, in <module>
    main()
  File "/Users/jacobl/cron_jobs/scripts/soupv2.py", line 96, in main
    img_url,description = find_image(site)
  File "/Users/jacobl/cron_jobs/scripts/soupv2.py", line 53, in find_image
    find_image(site)
  File "/Users/jacobl/cron_jobs/scripts/soupv2.py", line 45, in find_image
    soup = BeautifulSoup(requests.get(site).text, 'html.parser')
  File "/usr/local/lib/python3.9/site-packages/requests/api.py", line 76, in get
    return request('get', url, params=params, **kwargs)
  File "/usr/local/lib/python3.9/site-packages/requests/api.py", line 61, in request
    return session.request(method=method, url=url, **kwargs)
  File "/usr/local/lib/python3.9/site-packages/requests/sessions.py", line 530, in request
    resp = self.send(prep, **send_kwargs)
  File "/usr/local/lib/python3.9/site-packages/requests/sessions.py", line 637, in send
    adapter = self.get_adapter(url=request.url)
  File "/usr/local/lib/python3.9/site-packages/requests/sessions.py", line 730, in get_adapter
    raise InvalidSchema("No connection adapters were found for {!r}".format(url))
requests.exceptions.InvalidSchema: No connection adapters were found for "('https://apod.nasa.gov/apod/ap201208.html', '201208')"
https://apod.nasa.gov/apod/ap211226.html
https://apod.nasa.gov/apod/ap210503.html
https://apod.nasa.gov/apod/ap210307.html
https://apod.nasa.gov/apod/ap201129.html
https://apod.nasa.gov/apod/ap210502.html
https://apod.nasa.gov/apod/ap210908.html
https://apod.nasa.gov/apod/ap201119.html
https://apod.nasa.gov/apod/ap201017.html
https://apod.nasa.gov/apod/ap210408.html
https://apod.nasa.gov/apod/ap210425.html
https://apod.nasa.gov/apod/ap210828.html
https://apod.nasa.gov/apod/ap200922.html
https://apod.nasa.gov/apod/ap210824.html
https://apod.nasa.gov/apod/ap211021.html
https://apod.nasa.gov/apod/ap201218.html
https://apod.nasa.gov/apod/ap201129.html
https://apod.nasa.gov/apod/ap210301.html
https://apod.nasa.gov/apod/ap210526.html
https://apod.nasa.gov/apod/ap210413.html
https://apod.nasa.gov/apod/ap210731.html
https://apod.nasa.gov/apod/ap210522.html
https://apod.nasa.gov/apod/ap210630.html
('https://apod.nasa.gov/apod/ap210508.html', '210508')
Traceback (most recent call last):
  File "/Users/jacobl/cron_jobs/scripts/soupv2.py", line 48, in find_image
    img_url = img_tag.get('src')
AttributeError: 'NoneType' object has no attribute 'get'

During handling of the above exception, another exception occurred:

Traceback (most recent call last):
  File "/Users/jacobl/cron_jobs/scripts/soupv2.py", line 103, in <module>
    main()
  File "/Users/jacobl/cron_jobs/scripts/soupv2.py", line 96, in main
    img_url,description = find_image(site)
  File "/Users/jacobl/cron_jobs/scripts/soupv2.py", line 53, in find_image
    find_image(site)
  File "/Users/jacobl/cron_jobs/scripts/soupv2.py", line 45, in find_image
    soup = BeautifulSoup(requests.get(site).text, 'html.parser')
  File "/usr/local/lib/python3.9/site-packages/requests/api.py", line 76, in get
    return request('get', url, params=params, **kwargs)
  File "/usr/local/lib/python3.9/site-packages/requests/api.py", line 61, in request
    return session.request(method=method, url=url, **kwargs)
  File "/usr/local/lib/python3.9/site-packages/requests/sessions.py", line 530, in request
    resp = self.send(prep, **send_kwargs)
  File "/usr/local/lib/python3.9/site-packages/requests/sessions.py", line 637, in send
    adapter = self.get_adapter(url=request.url)
  File "/usr/local/lib/python3.9/site-packages/requests/sessions.py", line 730, in get_adapter
    raise InvalidSchema("No connection adapters were found for {!r}".format(url))
requests.exceptions.InvalidSchema: No connection adapters were found for "('https://apod.nasa.gov/apod/ap210508.html', '210508')"
rm: /Users/jacobl/wallpaper/*_up.jpg: No such file or directory
https://apod.nasa.gov/apod/ap210906.html
https://apod.nasa.gov/apod/ap210708.html
https://apod.nasa.gov/apod/ap200925.html
https://apod.nasa.gov/apod/ap201022.html
https://apod.nasa.gov/apod/ap200913.html
https://apod.nasa.gov/apod/ap211210.html
https://apod.nasa.gov/apod/ap210603.html
https://apod.nasa.gov/apod/ap211209.html
https://apod.nasa.gov/apod/ap210802.html
('https://apod.nasa.gov/apod/ap210310.html', '210310')
Traceback (most recent call last):
  File "/Users/jacobl/cron_jobs/scripts/soupv2.py", line 48, in find_image
    img_url = img_tag.get('src')
AttributeError: 'NoneType' object has no attribute 'get'

During handling of the above exception, another exception occurred:

Traceback (most recent call last):
  File "/Users/jacobl/cron_jobs/scripts/soupv2.py", line 103, in <module>
    main()
  File "/Users/jacobl/cron_jobs/scripts/soupv2.py", line 96, in main
    img_url,description = find_image(site)
  File "/Users/jacobl/cron_jobs/scripts/soupv2.py", line 53, in find_image
    find_image(site)
  File "/Users/jacobl/cron_jobs/scripts/soupv2.py", line 45, in find_image
    soup = BeautifulSoup(requests.get(site).text, 'html.parser')
  File "/usr/local/lib/python3.9/site-packages/requests/api.py", line 76, in get
    return request('get', url, params=params, **kwargs)
  File "/usr/local/lib/python3.9/site-packages/requests/api.py", line 61, in request
    return session.request(method=method, url=url, **kwargs)
  File "/usr/local/lib/python3.9/site-packages/requests/sessions.py", line 530, in request
    resp = self.send(prep, **send_kwargs)
  File "/usr/local/lib/python3.9/site-packages/requests/sessions.py", line 637, in send
    adapter = self.get_adapter(url=request.url)
  File "/usr/local/lib/python3.9/site-packages/requests/sessions.py", line 730, in get_adapter
    raise InvalidSchema("No connection adapters were found for {!r}".format(url))
requests.exceptions.InvalidSchema: No connection adapters were found for "('https://apod.nasa.gov/apod/ap210310.html', '210310')"
https://apod.nasa.gov/apod/ap200913.html
https://apod.nasa.gov/apod/ap210706.html
https://apod.nasa.gov/apod/ap201210.html
https://apod.nasa.gov/apod/ap201210.html
https://apod.nasa.gov/apod/ap210607.html
https://apod.nasa.gov/apod/ap210121.html
https://apod.nasa.gov/apod/ap211217.html
https://apod.nasa.gov/apod/ap210601.html
https://apod.nasa.gov/apod/ap210822.html
https://apod.nasa.gov/apod/ap210608.html
https://apod.nasa.gov/apod/ap210831.html
https://apod.nasa.gov/apod/ap210402.html
https://apod.nasa.gov/apod/ap210604.html
https://apod.nasa.gov/apod/ap210202.html
https://apod.nasa.gov/apod/ap210814.html
https://apod.nasa.gov/apod/ap210705.html
https://apod.nasa.gov/apod/ap210419.html
https://apod.nasa.gov/apod/ap200923.html
https://apod.nasa.gov/apod/ap201026.html
https://apod.nasa.gov/apod/ap210604.html
https://apod.nasa.gov/apod/ap210508.html
https://apod.nasa.gov/apod/ap201113.html
https://apod.nasa.gov/apod/ap210730.html
https://apod.nasa.gov/apod/ap210319.html
https://apod.nasa.gov/apod/ap211104.html
https://apod.nasa.gov/apod/ap201209.html
('https://apod.nasa.gov/apod/ap210424.html', '210424')
Traceback (most recent call last):
  File "/Users/jacobl/cron_jobs/scripts/soupv2.py", line 48, in find_image
    img_url = img_tag.get('src')
AttributeError: 'NoneType' object has no attribute 'get'

During handling of the above exception, another exception occurred:

Traceback (most recent call last):
  File "/Users/jacobl/cron_jobs/scripts/soupv2.py", line 103, in <module>
    main()
  File "/Users/jacobl/cron_jobs/scripts/soupv2.py", line 96, in main
    img_url,description = find_image(site)
  File "/Users/jacobl/cron_jobs/scripts/soupv2.py", line 53, in find_image
    find_image(site)
  File "/Users/jacobl/cron_jobs/scripts/soupv2.py", line 45, in find_image
    soup = BeautifulSoup(requests.get(site).text, 'html.parser')
  File "/usr/local/lib/python3.9/site-packages/requests/api.py", line 76, in get
    return request('get', url, params=params, **kwargs)
  File "/usr/local/lib/python3.9/site-packages/requests/api.py", line 61, in request
    return session.request(method=method, url=url, **kwargs)
  File "/usr/local/lib/python3.9/site-packages/requests/sessions.py", line 530, in request
    resp = self.send(prep, **send_kwargs)
  File "/usr/local/lib/python3.9/site-packages/requests/sessions.py", line 637, in send
    adapter = self.get_adapter(url=request.url)
  File "/usr/local/lib/python3.9/site-packages/requests/sessions.py", line 730, in get_adapter
    raise InvalidSchema("No connection adapters were found for {!r}".format(url))
requests.exceptions.InvalidSchema: No connection adapters were found for "('https://apod.nasa.gov/apod/ap210424.html', '210424')"
https://apod.nasa.gov/apod/ap201221.html
https://apod.nasa.gov/apod/ap210420.html
('https://apod.nasa.gov/apod/ap210901.html', '210901')
Traceback (most recent call last):
  File "/Users/jacobl/cron_jobs/scripts/soupv2.py", line 48, in find_image
    img_url = img_tag.get('src')
AttributeError: 'NoneType' object has no attribute 'get'

During handling of the above exception, another exception occurred:

Traceback (most recent call last):
  File "/Users/jacobl/cron_jobs/scripts/soupv2.py", line 103, in <module>
    main()
  File "/Users/jacobl/cron_jobs/scripts/soupv2.py", line 96, in main
    img_url,description = find_image(site)
  File "/Users/jacobl/cron_jobs/scripts/soupv2.py", line 53, in find_image
    find_image(site)
  File "/Users/jacobl/cron_jobs/scripts/soupv2.py", line 45, in find_image
    soup = BeautifulSoup(requests.get(site).text, 'html.parser')
  File "/usr/local/lib/python3.9/site-packages/requests/api.py", line 76, in get
    return request('get', url, params=params, **kwargs)
  File "/usr/local/lib/python3.9/site-packages/requests/api.py", line 61, in request
    return session.request(method=method, url=url, **kwargs)
  File "/usr/local/lib/python3.9/site-packages/requests/sessions.py", line 530, in request
    resp = self.send(prep, **send_kwargs)
  File "/usr/local/lib/python3.9/site-packages/requests/sessions.py", line 637, in send
    adapter = self.get_adapter(url=request.url)
  File "/usr/local/lib/python3.9/site-packages/requests/sessions.py", line 730, in get_adapter
    raise InvalidSchema("No connection adapters were found for {!r}".format(url))
requests.exceptions.InvalidSchema: No connection adapters were found for "('https://apod.nasa.gov/apod/ap210901.html', '210901')"
https://apod.nasa.gov/apod/ap211007.html
https://apod.nasa.gov/apod/ap211020.html
https://apod.nasa.gov/apod/ap210829.html
https://apod.nasa.gov/apod/ap210322.html
https://apod.nasa.gov/apod/ap210929.html
('https://apod.nasa.gov/apod/ap210630.html', '210630')
Traceback (most recent call last):
  File "/Users/jacobl/cron_jobs/scripts/soupv2.py", line 48, in find_image
    img_url = img_tag.get('src')
AttributeError: 'NoneType' object has no attribute 'get'

During handling of the above exception, another exception occurred:

Traceback (most recent call last):
  File "/Users/jacobl/cron_jobs/scripts/soupv2.py", line 103, in <module>
    main()
  File "/Users/jacobl/cron_jobs/scripts/soupv2.py", line 96, in main
    img_url,description = find_image(site)
  File "/Users/jacobl/cron_jobs/scripts/soupv2.py", line 53, in find_image
    find_image(site)
  File "/Users/jacobl/cron_jobs/scripts/soupv2.py", line 45, in find_image
    soup = BeautifulSoup(requests.get(site).text, 'html.parser')
  File "/usr/local/lib/python3.9/site-packages/requests/api.py", line 76, in get
    return request('get', url, params=params, **kwargs)
  File "/usr/local/lib/python3.9/site-packages/requests/api.py", line 61, in request
    return session.request(method=method, url=url, **kwargs)
  File "/usr/local/lib/python3.9/site-packages/requests/sessions.py", line 530, in request
    resp = self.send(prep, **send_kwargs)
  File "/usr/local/lib/python3.9/site-packages/requests/sessions.py", line 637, in send
    adapter = self.get_adapter(url=request.url)
  File "/usr/local/lib/python3.9/site-packages/requests/sessions.py", line 730, in get_adapter
    raise InvalidSchema("No connection adapters were found for {!r}".format(url))
requests.exceptions.InvalidSchema: No connection adapters were found for "('https://apod.nasa.gov/apod/ap210630.html', '210630')"
https://apod.nasa.gov/apod/ap211118.html
https://apod.nasa.gov/apod/ap210731.html
https://apod.nasa.gov/apod/ap201227.html
https://apod.nasa.gov/apod/ap211106.html
https://apod.nasa.gov/apod/ap210429.html
https://apod.nasa.gov/apod/ap210416.html
('https://apod.nasa.gov/apod/ap210924.html', '210924')
Traceback (most recent call last):
  File "/Users/jacobl/cron_jobs/scripts/soupv2.py", line 48, in find_image
    img_url = img_tag.get('src')
AttributeError: 'NoneType' object has no attribute 'get'

During handling of the above exception, another exception occurred:

Traceback (most recent call last):
  File "/Users/jacobl/cron_jobs/scripts/soupv2.py", line 103, in <module>
    main()
  File "/Users/jacobl/cron_jobs/scripts/soupv2.py", line 96, in main
    img_url,description = find_image(site)
  File "/Users/jacobl/cron_jobs/scripts/soupv2.py", line 53, in find_image
    find_image(site)
  File "/Users/jacobl/cron_jobs/scripts/soupv2.py", line 45, in find_image
    soup = BeautifulSoup(requests.get(site).text, 'html.parser')
  File "/usr/local/lib/python3.9/site-packages/requests/api.py", line 76, in get
    return request('get', url, params=params, **kwargs)
  File "/usr/local/lib/python3.9/site-packages/requests/api.py", line 61, in request
    return session.request(method=method, url=url, **kwargs)
  File "/usr/local/lib/python3.9/site-packages/requests/sessions.py", line 530, in request
    resp = self.send(prep, **send_kwargs)
  File "/usr/local/lib/python3.9/site-packages/requests/sessions.py", line 637, in send
    adapter = self.get_adapter(url=request.url)
  File "/usr/local/lib/python3.9/site-packages/requests/sessions.py", line 730, in get_adapter
    raise InvalidSchema("No connection adapters were found for {!r}".format(url))
requests.exceptions.InvalidSchema: No connection adapters were found for "('https://apod.nasa.gov/apod/ap210924.html', '210924')"
https://apod.nasa.gov/apod/ap211203.html
https://apod.nasa.gov/apod/ap211202.html
https://apod.nasa.gov/apod/ap210608.html
https://apod.nasa.gov/apod/ap210721.html
https://apod.nasa.gov/apod/ap210328.html
https://apod.nasa.gov/apod/ap210920.html
https://apod.nasa.gov/apod/ap210201.html
https://apod.nasa.gov/apod/ap211230.html
https://apod.nasa.gov/apod/ap201103.html
('https://apod.nasa.gov/apod/ap210606.html', '210606')
Traceback (most recent call last):
  File "/Users/jacobl/cron_jobs/scripts/soupv2.py", line 48, in find_image
    img_url = img_tag.get('src')
AttributeError: 'NoneType' object has no attribute 'get'

During handling of the above exception, another exception occurred:

Traceback (most recent call last):
  File "/Users/jacobl/cron_jobs/scripts/soupv2.py", line 103, in <module>
    main()
  File "/Users/jacobl/cron_jobs/scripts/soupv2.py", line 96, in main
    img_url,description = find_image(site)
  File "/Users/jacobl/cron_jobs/scripts/soupv2.py", line 53, in find_image
    find_image(site)
  File "/Users/jacobl/cron_jobs/scripts/soupv2.py", line 45, in find_image
    soup = BeautifulSoup(requests.get(site).text, 'html.parser')
  File "/usr/local/lib/python3.9/site-packages/requests/api.py", line 76, in get
    return request('get', url, params=params, **kwargs)
  File "/usr/local/lib/python3.9/site-packages/requests/api.py", line 61, in request
    return session.request(method=method, url=url, **kwargs)
  File "/usr/local/lib/python3.9/site-packages/requests/sessions.py", line 530, in request
    resp = self.send(prep, **send_kwargs)
  File "/usr/local/lib/python3.9/site-packages/requests/sessions.py", line 637, in send
    adapter = self.get_adapter(url=request.url)
  File "/usr/local/lib/python3.9/site-packages/requests/sessions.py", line 730, in get_adapter
    raise InvalidSchema("No connection adapters were found for {!r}".format(url))
requests.exceptions.InvalidSchema: No connection adapters were found for "('https://apod.nasa.gov/apod/ap210606.html', '210606')"
https://apod.nasa.gov/apod/ap211228.html
('https://apod.nasa.gov/apod/ap220110.html', '220110')
Traceback (most recent call last):
  File "/Users/jacobl/cron_jobs/scripts/soupv2.py", line 48, in find_image
    img_url = img_tag.get('src')
AttributeError: 'NoneType' object has no attribute 'get'

During handling of the above exception, another exception occurred:

Traceback (most recent call last):
  File "/Users/jacobl/cron_jobs/scripts/soupv2.py", line 103, in <module>
    main()
  File "/Users/jacobl/cron_jobs/scripts/soupv2.py", line 96, in main
    img_url,description = find_image(site)
  File "/Users/jacobl/cron_jobs/scripts/soupv2.py", line 53, in find_image
    find_image(site)
  File "/Users/jacobl/cron_jobs/scripts/soupv2.py", line 45, in find_image
    soup = BeautifulSoup(requests.get(site).text, 'html.parser')
  File "/usr/local/lib/python3.9/site-packages/requests/api.py", line 76, in get
    return request('get', url, params=params, **kwargs)
  File "/usr/local/lib/python3.9/site-packages/requests/api.py", line 61, in request
    return session.request(method=method, url=url, **kwargs)
  File "/usr/local/lib/python3.9/site-packages/requests/sessions.py", line 530, in request
    resp = self.send(prep, **send_kwargs)
  File "/usr/local/lib/python3.9/site-packages/requests/sessions.py", line 637, in send
    adapter = self.get_adapter(url=request.url)
  File "/usr/local/lib/python3.9/site-packages/requests/sessions.py", line 730, in get_adapter
    raise InvalidSchema("No connection adapters were found for {!r}".format(url))
requests.exceptions.InvalidSchema: No connection adapters were found for "('https://apod.nasa.gov/apod/ap220110.html', '220110')"
rm: /Users/jacobl/wallpaper/*_up.jpg: No such file or directory
https://apod.nasa.gov/apod/ap210703.html
https://apod.nasa.gov/apod/ap201007.html
https://apod.nasa.gov/apod/ap211217.html
https://apod.nasa.gov/apod/ap210613.html
('https://apod.nasa.gov/apod/ap211004.html', '211004')
Traceback (most recent call last):
  File "/Users/jacobl/cron_jobs/scripts/soupv2.py", line 48, in find_image
    img_url = img_tag.get('src')
AttributeError: 'NoneType' object has no attribute 'get'

During handling of the above exception, another exception occurred:

Traceback (most recent call last):
  File "/Users/jacobl/cron_jobs/scripts/soupv2.py", line 103, in <module>
    main()
  File "/Users/jacobl/cron_jobs/scripts/soupv2.py", line 96, in main
    img_url,description = find_image(site)
  File "/Users/jacobl/cron_jobs/scripts/soupv2.py", line 53, in find_image
    find_image(site)
  File "/Users/jacobl/cron_jobs/scripts/soupv2.py", line 45, in find_image
    soup = BeautifulSoup(requests.get(site).text, 'html.parser')
  File "/usr/local/lib/python3.9/site-packages/requests/api.py", line 76, in get
    return request('get', url, params=params, **kwargs)
  File "/usr/local/lib/python3.9/site-packages/requests/api.py", line 61, in request
    return session.request(method=method, url=url, **kwargs)
  File "/usr/local/lib/python3.9/site-packages/requests/sessions.py", line 530, in request
    resp = self.send(prep, **send_kwargs)
  File "/usr/local/lib/python3.9/site-packages/requests/sessions.py", line 637, in send
    adapter = self.get_adapter(url=request.url)
  File "/usr/local/lib/python3.9/site-packages/requests/sessions.py", line 730, in get_adapter
    raise InvalidSchema("No connection adapters were found for {!r}".format(url))
requests.exceptions.InvalidSchema: No connection adapters were found for "('https://apod.nasa.gov/apod/ap211004.html', '211004')"
rm: /Users/jacobl/wallpaper/*_up.jpg: No such file or directory
https://apod.nasa.gov/apod/ap210323.html
https://apod.nasa.gov/apod/ap210412.html
https://apod.nasa.gov/apod/ap211127.html
https://apod.nasa.gov/apod/ap211003.html
https://apod.nasa.gov/apod/ap210121.html
https://apod.nasa.gov/apod/ap211001.html
https://apod.nasa.gov/apod/ap210801.html
https://apod.nasa.gov/apod/ap211211.html
https://apod.nasa.gov/apod/ap210221.html
https://apod.nasa.gov/apod/ap210130.html
https://apod.nasa.gov/apod/ap210425.html
https://apod.nasa.gov/apod/ap211118.html
https://apod.nasa.gov/apod/ap201209.html
('https://apod.nasa.gov/apod/ap210628.html', '210628')
Traceback (most recent call last):
  File "/Users/jacobl/cron_jobs/scripts/soupv2.py", line 48, in find_image
    img_url = img_tag.get('src')
AttributeError: 'NoneType' object has no attribute 'get'

During handling of the above exception, another exception occurred:

Traceback (most recent call last):
  File "/Users/jacobl/cron_jobs/scripts/soupv2.py", line 103, in <module>
    main()
  File "/Users/jacobl/cron_jobs/scripts/soupv2.py", line 96, in main
    img_url,description = find_image(site)
  File "/Users/jacobl/cron_jobs/scripts/soupv2.py", line 53, in find_image
    find_image(site)
  File "/Users/jacobl/cron_jobs/scripts/soupv2.py", line 45, in find_image
    soup = BeautifulSoup(requests.get(site).text, 'html.parser')
  File "/usr/local/lib/python3.9/site-packages/requests/api.py", line 76, in get
    return request('get', url, params=params, **kwargs)
  File "/usr/local/lib/python3.9/site-packages/requests/api.py", line 61, in request
    return session.request(method=method, url=url, **kwargs)
  File "/usr/local/lib/python3.9/site-packages/requests/sessions.py", line 530, in request
    resp = self.send(prep, **send_kwargs)
  File "/usr/local/lib/python3.9/site-packages/requests/sessions.py", line 637, in send
    adapter = self.get_adapter(url=request.url)
  File "/usr/local/lib/python3.9/site-packages/requests/sessions.py", line 730, in get_adapter
    raise InvalidSchema("No connection adapters were found for {!r}".format(url))
requests.exceptions.InvalidSchema: No connection adapters were found for "('https://apod.nasa.gov/apod/ap210628.html', '210628')"
rm: /Users/jacobl/wallpaper/*_up.jpg: No such file or directory
https://apod.nasa.gov/apod/ap210122.html
https://apod.nasa.gov/apod/ap211031.html
https://apod.nasa.gov/apod/ap210409.html
https://apod.nasa.gov/apod/ap200925.html
https://apod.nasa.gov/apod/ap200915.html
https://apod.nasa.gov/apod/ap201022.html
https://apod.nasa.gov/apod/ap201011.html
https://apod.nasa.gov/apod/ap210126.html
https://apod.nasa.gov/apod/ap210904.html
https://apod.nasa.gov/apod/ap211121.html
https://apod.nasa.gov/apod/ap211105.html
https://apod.nasa.gov/apod/ap210429.html
https://apod.nasa.gov/apod/ap210116.html
https://apod.nasa.gov/apod/ap210716.html
https://apod.nasa.gov/apod/ap210808.html
https://apod.nasa.gov/apod/ap210331.html
https://apod.nasa.gov/apod/ap210614.html
https://apod.nasa.gov/apod/ap201114.html
https://apod.nasa.gov/apod/ap210312.html
https://apod.nasa.gov/apod/ap200928.html
https://apod.nasa.gov/apod/ap210927.html
https://apod.nasa.gov/apod/ap210913.html
https://apod.nasa.gov/apod/ap201220.html
https://apod.nasa.gov/apod/ap211010.html
('https://apod.nasa.gov/apod/ap210723.html', '210723')
Traceback (most recent call last):
  File "/Users/jacobl/cron_jobs/scripts/soupv2.py", line 48, in find_image
    img_url = img_tag.get('src')
AttributeError: 'NoneType' object has no attribute 'get'

During handling of the above exception, another exception occurred:

Traceback (most recent call last):
  File "/Users/jacobl/cron_jobs/scripts/soupv2.py", line 103, in <module>
    main()
  File "/Users/jacobl/cron_jobs/scripts/soupv2.py", line 96, in main
    img_url,description = find_image(site)
  File "/Users/jacobl/cron_jobs/scripts/soupv2.py", line 53, in find_image
    find_image(site)
  File "/Users/jacobl/cron_jobs/scripts/soupv2.py", line 45, in find_image
    soup = BeautifulSoup(requests.get(site).text, 'html.parser')
  File "/usr/local/lib/python3.9/site-packages/requests/api.py", line 76, in get
    return request('get', url, params=params, **kwargs)
  File "/usr/local/lib/python3.9/site-packages/requests/api.py", line 61, in request
    return session.request(method=method, url=url, **kwargs)
  File "/usr/local/lib/python3.9/site-packages/requests/sessions.py", line 530, in request
    resp = self.send(prep, **send_kwargs)
  File "/usr/local/lib/python3.9/site-packages/requests/sessions.py", line 637, in send
    adapter = self.get_adapter(url=request.url)
  File "/usr/local/lib/python3.9/site-packages/requests/sessions.py", line 730, in get_adapter
    raise InvalidSchema("No connection adapters were found for {!r}".format(url))
requests.exceptions.InvalidSchema: No connection adapters were found for "('https://apod.nasa.gov/apod/ap210723.html', '210723')"
https://apod.nasa.gov/apod/ap210705.html
https://apod.nasa.gov/apod/ap210601.html
https://apod.nasa.gov/apod/ap210724.html
https://apod.nasa.gov/apod/ap201231.html
https://apod.nasa.gov/apod/ap210502.html
https://apod.nasa.gov/apod/ap210825.html
('https://apod.nasa.gov/apod/ap201229.html', '201229')
Traceback (most recent call last):
  File "/Users/jacobl/cron_jobs/scripts/soupv2.py", line 48, in find_image
    img_url = img_tag.get('src')
AttributeError: 'NoneType' object has no attribute 'get'

During handling of the above exception, another exception occurred:

Traceback (most recent call last):
  File "/Users/jacobl/cron_jobs/scripts/soupv2.py", line 103, in <module>
    main()
  File "/Users/jacobl/cron_jobs/scripts/soupv2.py", line 96, in main
    img_url,description = find_image(site)
  File "/Users/jacobl/cron_jobs/scripts/soupv2.py", line 53, in find_image
    find_image(site)
  File "/Users/jacobl/cron_jobs/scripts/soupv2.py", line 45, in find_image
    soup = BeautifulSoup(requests.get(site).text, 'html.parser')
  File "/usr/local/lib/python3.9/site-packages/requests/api.py", line 76, in get
    return request('get', url, params=params, **kwargs)
  File "/usr/local/lib/python3.9/site-packages/requests/api.py", line 61, in request
    return session.request(method=method, url=url, **kwargs)
  File "/usr/local/lib/python3.9/site-packages/requests/sessions.py", line 530, in request
    resp = self.send(prep, **send_kwargs)
  File "/usr/local/lib/python3.9/site-packages/requests/sessions.py", line 637, in send
    adapter = self.get_adapter(url=request.url)
  File "/usr/local/lib/python3.9/site-packages/requests/sessions.py", line 730, in get_adapter
    raise InvalidSchema("No connection adapters were found for {!r}".format(url))
requests.exceptions.InvalidSchema: No connection adapters were found for "('https://apod.nasa.gov/apod/ap201229.html', '201229')"
https://apod.nasa.gov/apod/ap210928.html
('https://apod.nasa.gov/apod/ap211103.html', '211103')
Traceback (most recent call last):
  File "/Users/jacobl/cron_jobs/scripts/soupv2.py", line 48, in find_image
    img_url = img_tag.get('src')
AttributeError: 'NoneType' object has no attribute 'get'

During handling of the above exception, another exception occurred:

Traceback (most recent call last):
  File "/Users/jacobl/cron_jobs/scripts/soupv2.py", line 103, in <module>
    main()
  File "/Users/jacobl/cron_jobs/scripts/soupv2.py", line 96, in main
    img_url,description = find_image(site)
  File "/Users/jacobl/cron_jobs/scripts/soupv2.py", line 53, in find_image
    find_image(site)
  File "/Users/jacobl/cron_jobs/scripts/soupv2.py", line 45, in find_image
    soup = BeautifulSoup(requests.get(site).text, 'html.parser')
  File "/usr/local/lib/python3.9/site-packages/requests/api.py", line 76, in get
    return request('get', url, params=params, **kwargs)
  File "/usr/local/lib/python3.9/site-packages/requests/api.py", line 61, in request
    return session.request(method=method, url=url, **kwargs)
  File "/usr/local/lib/python3.9/site-packages/requests/sessions.py", line 530, in request
    resp = self.send(prep, **send_kwargs)
  File "/usr/local/lib/python3.9/site-packages/requests/sessions.py", line 637, in send
    adapter = self.get_adapter(url=request.url)
  File "/usr/local/lib/python3.9/site-packages/requests/sessions.py", line 730, in get_adapter
    raise InvalidSchema("No connection adapters were found for {!r}".format(url))
requests.exceptions.InvalidSchema: No connection adapters were found for "('https://apod.nasa.gov/apod/ap211103.html', '211103')"
rm: /Users/jacobl/wallpaper/*_up.jpg: No such file or directory
https://apod.nasa.gov/apod/ap201212.html
https://apod.nasa.gov/apod/ap210501.html
https://apod.nasa.gov/apod/ap210421.html
https://apod.nasa.gov/apod/ap210904.html
https://apod.nasa.gov/apod/ap210822.html
https://apod.nasa.gov/apod/ap210813.html
https://apod.nasa.gov/apod/ap211109.html
https://apod.nasa.gov/apod/ap210916.html
https://apod.nasa.gov/apod/ap201026.html
https://apod.nasa.gov/apod/ap211128.html
https://apod.nasa.gov/apod/ap210904.html
https://apod.nasa.gov/apod/ap220117.html
https://apod.nasa.gov/apod/ap210601.html
https://apod.nasa.gov/apod/ap210608.html
https://apod.nasa.gov/apod/ap210907.html
https://apod.nasa.gov/apod/ap210329.html
https://apod.nasa.gov/apod/ap210819.html
https://apod.nasa.gov/apod/ap201024.html
https://apod.nasa.gov/apod/ap211023.html
https://apod.nasa.gov/apod/ap220111.html
https://apod.nasa.gov/apod/ap211121.html
https://apod.nasa.gov/apod/ap211114.html
https://apod.nasa.gov/apod/ap210818.html
https://apod.nasa.gov/apod/ap210209.html
('https://apod.nasa.gov/apod/ap211026.html', '211026')
Traceback (most recent call last):
  File "/Users/jacobl/cron_jobs/scripts/soupv2.py", line 48, in find_image
    img_url = img_tag.get('src')
AttributeError: 'NoneType' object has no attribute 'get'

During handling of the above exception, another exception occurred:

Traceback (most recent call last):
  File "/Users/jacobl/cron_jobs/scripts/soupv2.py", line 103, in <module>
    main()
  File "/Users/jacobl/cron_jobs/scripts/soupv2.py", line 96, in main
    img_url,description = find_image(site)
  File "/Users/jacobl/cron_jobs/scripts/soupv2.py", line 53, in find_image
    find_image(site)
  File "/Users/jacobl/cron_jobs/scripts/soupv2.py", line 45, in find_image
    soup = BeautifulSoup(requests.get(site).text, 'html.parser')
  File "/usr/local/lib/python3.9/site-packages/requests/api.py", line 76, in get
    return request('get', url, params=params, **kwargs)
  File "/usr/local/lib/python3.9/site-packages/requests/api.py", line 61, in request
    return session.request(method=method, url=url, **kwargs)
  File "/usr/local/lib/python3.9/site-packages/requests/sessions.py", line 530, in request
    resp = self.send(prep, **send_kwargs)
  File "/usr/local/lib/python3.9/site-packages/requests/sessions.py", line 637, in send
    adapter = self.get_adapter(url=request.url)
  File "/usr/local/lib/python3.9/site-packages/requests/sessions.py", line 730, in get_adapter
    raise InvalidSchema("No connection adapters were found for {!r}".format(url))
requests.exceptions.InvalidSchema: No connection adapters were found for "('https://apod.nasa.gov/apod/ap211026.html', '211026')"
https://apod.nasa.gov/apod/ap210428.html
https://apod.nasa.gov/apod/ap210515.html
https://apod.nasa.gov/apod/ap210616.html
https://apod.nasa.gov/apod/ap201210.html
https://apod.nasa.gov/apod/ap210206.html
https://apod.nasa.gov/apod/ap211104.html
https://apod.nasa.gov/apod/ap201121.html
https://apod.nasa.gov/apod/ap210723.html
https://apod.nasa.gov/apod/ap210525.html
('https://apod.nasa.gov/apod/ap210922.html', '210922')
Traceback (most recent call last):
  File "/Users/jacobl/cron_jobs/scripts/soupv2.py", line 48, in find_image
    img_url = img_tag.get('src')
AttributeError: 'NoneType' object has no attribute 'get'

During handling of the above exception, another exception occurred:

Traceback (most recent call last):
  File "/Users/jacobl/cron_jobs/scripts/soupv2.py", line 103, in <module>
    main()
  File "/Users/jacobl/cron_jobs/scripts/soupv2.py", line 96, in main
    img_url,description = find_image(site)
  File "/Users/jacobl/cron_jobs/scripts/soupv2.py", line 53, in find_image
    find_image(site)
  File "/Users/jacobl/cron_jobs/scripts/soupv2.py", line 45, in find_image
    soup = BeautifulSoup(requests.get(site).text, 'html.parser')
  File "/usr/local/lib/python3.9/site-packages/requests/api.py", line 76, in get
    return request('get', url, params=params, **kwargs)
  File "/usr/local/lib/python3.9/site-packages/requests/api.py", line 61, in request
    return session.request(method=method, url=url, **kwargs)
  File "/usr/local/lib/python3.9/site-packages/requests/sessions.py", line 530, in request
    resp = self.send(prep, **send_kwargs)
  File "/usr/local/lib/python3.9/site-packages/requests/sessions.py", line 637, in send
    adapter = self.get_adapter(url=request.url)
  File "/usr/local/lib/python3.9/site-packages/requests/sessions.py", line 730, in get_adapter
    raise InvalidSchema("No connection adapters were found for {!r}".format(url))
requests.exceptions.InvalidSchema: No connection adapters were found for "('https://apod.nasa.gov/apod/ap210922.html', '210922')"
https://apod.nasa.gov/apod/ap211017.html
https://apod.nasa.gov/apod/ap210213.html
https://apod.nasa.gov/apod/ap201024.html
https://apod.nasa.gov/apod/ap210819.html
https://apod.nasa.gov/apod/ap201231.html
https://apod.nasa.gov/apod/ap210221.html
https://apod.nasa.gov/apod/ap210627.html
https://apod.nasa.gov/apod/ap210224.html
https://apod.nasa.gov/apod/ap210215.html
('https://apod.nasa.gov/apod/ap210331.html', '210331')
Traceback (most recent call last):
  File "/Users/jacobl/cron_jobs/scripts/soupv2.py", line 48, in find_image
    img_url = img_tag.get('src')
AttributeError: 'NoneType' object has no attribute 'get'

During handling of the above exception, another exception occurred:

Traceback (most recent call last):
  File "/Users/jacobl/cron_jobs/scripts/soupv2.py", line 103, in <module>
    main()
  File "/Users/jacobl/cron_jobs/scripts/soupv2.py", line 96, in main
    img_url,description = find_image(site)
  File "/Users/jacobl/cron_jobs/scripts/soupv2.py", line 53, in find_image
    find_image(site)
  File "/Users/jacobl/cron_jobs/scripts/soupv2.py", line 45, in find_image
    soup = BeautifulSoup(requests.get(site).text, 'html.parser')
  File "/usr/local/lib/python3.9/site-packages/requests/api.py", line 76, in get
    return request('get', url, params=params, **kwargs)
  File "/usr/local/lib/python3.9/site-packages/requests/api.py", line 61, in request
    return session.request(method=method, url=url, **kwargs)
  File "/usr/local/lib/python3.9/site-packages/requests/sessions.py", line 530, in request
    resp = self.send(prep, **send_kwargs)
  File "/usr/local/lib/python3.9/site-packages/requests/sessions.py", line 637, in send
    adapter = self.get_adapter(url=request.url)
  File "/usr/local/lib/python3.9/site-packages/requests/sessions.py", line 730, in get_adapter
    raise InvalidSchema("No connection adapters were found for {!r}".format(url))
requests.exceptions.InvalidSchema: No connection adapters were found for "('https://apod.nasa.gov/apod/ap210331.html', '210331')"
https://apod.nasa.gov/apod/ap211024.html
https://apod.nasa.gov/apod/ap201216.html
('https://apod.nasa.gov/apod/ap210813.html', '210813')
Traceback (most recent call last):
  File "/Users/jacobl/cron_jobs/scripts/soupv2.py", line 48, in find_image
    img_url = img_tag.get('src')
AttributeError: 'NoneType' object has no attribute 'get'

During handling of the above exception, another exception occurred:

Traceback (most recent call last):
  File "/Users/jacobl/cron_jobs/scripts/soupv2.py", line 103, in <module>
    main()
  File "/Users/jacobl/cron_jobs/scripts/soupv2.py", line 96, in main
    img_url,description = find_image(site)
  File "/Users/jacobl/cron_jobs/scripts/soupv2.py", line 53, in find_image
    find_image(site)
  File "/Users/jacobl/cron_jobs/scripts/soupv2.py", line 45, in find_image
    soup = BeautifulSoup(requests.get(site).text, 'html.parser')
  File "/usr/local/lib/python3.9/site-packages/requests/api.py", line 76, in get
    return request('get', url, params=params, **kwargs)
  File "/usr/local/lib/python3.9/site-packages/requests/api.py", line 61, in request
    return session.request(method=method, url=url, **kwargs)
  File "/usr/local/lib/python3.9/site-packages/requests/sessions.py", line 530, in request
    resp = self.send(prep, **send_kwargs)
  File "/usr/local/lib/python3.9/site-packages/requests/sessions.py", line 637, in send
    adapter = self.get_adapter(url=request.url)
  File "/usr/local/lib/python3.9/site-packages/requests/sessions.py", line 730, in get_adapter
    raise InvalidSchema("No connection adapters were found for {!r}".format(url))
requests.exceptions.InvalidSchema: No connection adapters were found for "('https://apod.nasa.gov/apod/ap210813.html', '210813')"
https://apod.nasa.gov/apod/ap211013.html
https://apod.nasa.gov/apod/ap210625.html
https://apod.nasa.gov/apod/ap210909.html
https://apod.nasa.gov/apod/ap210307.html
https://apod.nasa.gov/apod/ap210122.html
https://apod.nasa.gov/apod/ap201112.html
https://apod.nasa.gov/apod/ap210310.html
https://apod.nasa.gov/apod/ap210630.html
('https://apod.nasa.gov/apod/ap201207.html', '201207')
Traceback (most recent call last):
  File "/Users/jacobl/cron_jobs/scripts/soupv2.py", line 48, in find_image
    img_url = img_tag.get('src')
AttributeError: 'NoneType' object has no attribute 'get'

During handling of the above exception, another exception occurred:

Traceback (most recent call last):
  File "/Users/jacobl/cron_jobs/scripts/soupv2.py", line 103, in <module>
    main()
  File "/Users/jacobl/cron_jobs/scripts/soupv2.py", line 96, in main
    img_url,description = find_image(site)
  File "/Users/jacobl/cron_jobs/scripts/soupv2.py", line 53, in find_image
    find_image(site)
  File "/Users/jacobl/cron_jobs/scripts/soupv2.py", line 45, in find_image
    soup = BeautifulSoup(requests.get(site).text, 'html.parser')
  File "/usr/local/lib/python3.9/site-packages/requests/api.py", line 76, in get
    return request('get', url, params=params, **kwargs)
  File "/usr/local/lib/python3.9/site-packages/requests/api.py", line 61, in request
    return session.request(method=method, url=url, **kwargs)
  File "/usr/local/lib/python3.9/site-packages/requests/sessions.py", line 530, in request
    resp = self.send(prep, **send_kwargs)
  File "/usr/local/lib/python3.9/site-packages/requests/sessions.py", line 637, in send
    adapter = self.get_adapter(url=request.url)
  File "/usr/local/lib/python3.9/site-packages/requests/sessions.py", line 730, in get_adapter
    raise InvalidSchema("No connection adapters were found for {!r}".format(url))
requests.exceptions.InvalidSchema: No connection adapters were found for "('https://apod.nasa.gov/apod/ap201207.html', '201207')"
https://apod.nasa.gov/apod/ap210525.html
('https://apod.nasa.gov/apod/ap210322.html', '210322')
Traceback (most recent call last):
  File "/Users/jacobl/cron_jobs/scripts/soupv2.py", line 48, in find_image
    img_url = img_tag.get('src')
AttributeError: 'NoneType' object has no attribute 'get'

During handling of the above exception, another exception occurred:

Traceback (most recent call last):
  File "/Users/jacobl/cron_jobs/scripts/soupv2.py", line 103, in <module>
    main()
  File "/Users/jacobl/cron_jobs/scripts/soupv2.py", line 96, in main
    img_url,description = find_image(site)
  File "/Users/jacobl/cron_jobs/scripts/soupv2.py", line 53, in find_image
    find_image(site)
  File "/Users/jacobl/cron_jobs/scripts/soupv2.py", line 45, in find_image
    soup = BeautifulSoup(requests.get(site).text, 'html.parser')
  File "/usr/local/lib/python3.9/site-packages/requests/api.py", line 76, in get
    return request('get', url, params=params, **kwargs)
  File "/usr/local/lib/python3.9/site-packages/requests/api.py", line 61, in request
    return session.request(method=method, url=url, **kwargs)
  File "/usr/local/lib/python3.9/site-packages/requests/sessions.py", line 530, in request
    resp = self.send(prep, **send_kwargs)
  File "/usr/local/lib/python3.9/site-packages/requests/sessions.py", line 637, in send
    adapter = self.get_adapter(url=request.url)
  File "/usr/local/lib/python3.9/site-packages/requests/sessions.py", line 730, in get_adapter
    raise InvalidSchema("No connection adapters were found for {!r}".format(url))
requests.exceptions.InvalidSchema: No connection adapters were found for "('https://apod.nasa.gov/apod/ap210322.html', '210322')"
rm: /Users/jacobl/wallpaper/*_up.jpg: No such file or directory
https://apod.nasa.gov/apod/ap200908.html
https://apod.nasa.gov/apod/ap210519.html
https://apod.nasa.gov/apod/ap210201.html
https://apod.nasa.gov/apod/ap210925.html
https://apod.nasa.gov/apod/ap210319.html
https://apod.nasa.gov/apod/ap210725.html
https://apod.nasa.gov/apod/ap210303.html
https://apod.nasa.gov/apod/ap210804.html
https://apod.nasa.gov/apod/ap210123.html
https://apod.nasa.gov/apod/ap201202.html
https://apod.nasa.gov/apod/ap210406.html
https://apod.nasa.gov/apod/ap210814.html
https://apod.nasa.gov/apod/ap210728.html
https://apod.nasa.gov/apod/ap201026.html
https://apod.nasa.gov/apod/ap201223.html
https://apod.nasa.gov/apod/ap210606.html
https://apod.nasa.gov/apod/ap210314.html
https://apod.nasa.gov/apod/ap210405.html
https://apod.nasa.gov/apod/ap201007.html
https://apod.nasa.gov/apod/ap211111.html
https://apod.nasa.gov/apod/ap201209.html
('https://apod.nasa.gov/apod/ap210529.html', '210529')
Traceback (most recent call last):
  File "/Users/jacobl/cron_jobs/scripts/soupv2.py", line 48, in find_image
    img_url = img_tag.get('src')
AttributeError: 'NoneType' object has no attribute 'get'

During handling of the above exception, another exception occurred:

Traceback (most recent call last):
  File "/Users/jacobl/cron_jobs/scripts/soupv2.py", line 103, in <module>
    main()
  File "/Users/jacobl/cron_jobs/scripts/soupv2.py", line 96, in main
    img_url,description = find_image(site)
  File "/Users/jacobl/cron_jobs/scripts/soupv2.py", line 53, in find_image
    find_image(site)
  File "/Users/jacobl/cron_jobs/scripts/soupv2.py", line 45, in find_image
    soup = BeautifulSoup(requests.get(site).text, 'html.parser')
  File "/usr/local/lib/python3.9/site-packages/requests/api.py", line 76, in get
    return request('get', url, params=params, **kwargs)
  File "/usr/local/lib/python3.9/site-packages/requests/api.py", line 61, in request
    return session.request(method=method, url=url, **kwargs)
  File "/usr/local/lib/python3.9/site-packages/requests/sessions.py", line 530, in request
    resp = self.send(prep, **send_kwargs)
  File "/usr/local/lib/python3.9/site-packages/requests/sessions.py", line 637, in send
    adapter = self.get_adapter(url=request.url)
  File "/usr/local/lib/python3.9/site-packages/requests/sessions.py", line 730, in get_adapter
    raise InvalidSchema("No connection adapters were found for {!r}".format(url))
requests.exceptions.InvalidSchema: No connection adapters were found for "('https://apod.nasa.gov/apod/ap210529.html', '210529')"
https://apod.nasa.gov/apod/ap211017.html
https://apod.nasa.gov/apod/ap210513.html
https://apod.nasa.gov/apod/ap210928.html
('https://apod.nasa.gov/apod/ap201024.html', '201024')
Traceback (most recent call last):
  File "/Users/jacobl/cron_jobs/scripts/soupv2.py", line 48, in find_image
    img_url = img_tag.get('src')
AttributeError: 'NoneType' object has no attribute 'get'

During handling of the above exception, another exception occurred:

Traceback (most recent call last):
  File "/Users/jacobl/cron_jobs/scripts/soupv2.py", line 103, in <module>
    main()
  File "/Users/jacobl/cron_jobs/scripts/soupv2.py", line 96, in main
    img_url,description = find_image(site)
  File "/Users/jacobl/cron_jobs/scripts/soupv2.py", line 53, in find_image
    find_image(site)
  File "/Users/jacobl/cron_jobs/scripts/soupv2.py", line 45, in find_image
    soup = BeautifulSoup(requests.get(site).text, 'html.parser')
  File "/usr/local/lib/python3.9/site-packages/requests/api.py", line 76, in get
    return request('get', url, params=params, **kwargs)
  File "/usr/local/lib/python3.9/site-packages/requests/api.py", line 61, in request
    return session.request(method=method, url=url, **kwargs)
  File "/usr/local/lib/python3.9/site-packages/requests/sessions.py", line 530, in request
    resp = self.send(prep, **send_kwargs)
  File "/usr/local/lib/python3.9/site-packages/requests/sessions.py", line 637, in send
    adapter = self.get_adapter(url=request.url)
  File "/usr/local/lib/python3.9/site-packages/requests/sessions.py", line 730, in get_adapter
    raise InvalidSchema("No connection adapters were found for {!r}".format(url))
requests.exceptions.InvalidSchema: No connection adapters were found for "('https://apod.nasa.gov/apod/ap201024.html', '201024')"
https://apod.nasa.gov/apod/ap210115.html
https://apod.nasa.gov/apod/ap211013.html
https://apod.nasa.gov/apod/ap201109.html
https://apod.nasa.gov/apod/ap211124.html
https://apod.nasa.gov/apod/ap211130.html
('https://apod.nasa.gov/apod/ap210912.html', '210912')
Traceback (most recent call last):
  File "/Users/jacobl/cron_jobs/scripts/soupv2.py", line 48, in find_image
    img_url = img_tag.get('src')
AttributeError: 'NoneType' object has no attribute 'get'

During handling of the above exception, another exception occurred:

Traceback (most recent call last):
  File "/Users/jacobl/cron_jobs/scripts/soupv2.py", line 103, in <module>
    main()
  File "/Users/jacobl/cron_jobs/scripts/soupv2.py", line 96, in main
    img_url,description = find_image(site)
  File "/Users/jacobl/cron_jobs/scripts/soupv2.py", line 53, in find_image
    find_image(site)
  File "/Users/jacobl/cron_jobs/scripts/soupv2.py", line 45, in find_image
    soup = BeautifulSoup(requests.get(site).text, 'html.parser')
  File "/usr/local/lib/python3.9/site-packages/requests/api.py", line 76, in get
    return request('get', url, params=params, **kwargs)
  File "/usr/local/lib/python3.9/site-packages/requests/api.py", line 61, in request
    return session.request(method=method, url=url, **kwargs)
  File "/usr/local/lib/python3.9/site-packages/requests/sessions.py", line 530, in request
    resp = self.send(prep, **send_kwargs)
  File "/usr/local/lib/python3.9/site-packages/requests/sessions.py", line 637, in send
    adapter = self.get_adapter(url=request.url)
  File "/usr/local/lib/python3.9/site-packages/requests/sessions.py", line 730, in get_adapter
    raise InvalidSchema("No connection adapters were found for {!r}".format(url))
requests.exceptions.InvalidSchema: No connection adapters were found for "('https://apod.nasa.gov/apod/ap210912.html', '210912')"
https://apod.nasa.gov/apod/ap211210.html
https://apod.nasa.gov/apod/ap210318.html
https://apod.nasa.gov/apod/ap210710.html
https://apod.nasa.gov/apod/ap211102.html
https://apod.nasa.gov/apod/ap211016.html
https://apod.nasa.gov/apod/ap210215.html
('https://apod.nasa.gov/apod/ap200928.html', '200928')
Traceback (most recent call last):
  File "/Users/jacobl/cron_jobs/scripts/soupv2.py", line 48, in find_image
    img_url = img_tag.get('src')
AttributeError: 'NoneType' object has no attribute 'get'

During handling of the above exception, another exception occurred:

Traceback (most recent call last):
  File "/Users/jacobl/cron_jobs/scripts/soupv2.py", line 103, in <module>
    main()
  File "/Users/jacobl/cron_jobs/scripts/soupv2.py", line 96, in main
    img_url,description = find_image(site)
  File "/Users/jacobl/cron_jobs/scripts/soupv2.py", line 53, in find_image
    find_image(site)
  File "/Users/jacobl/cron_jobs/scripts/soupv2.py", line 45, in find_image
    soup = BeautifulSoup(requests.get(site).text, 'html.parser')
  File "/usr/local/lib/python3.9/site-packages/requests/api.py", line 76, in get
    return request('get', url, params=params, **kwargs)
  File "/usr/local/lib/python3.9/site-packages/requests/api.py", line 61, in request
    return session.request(method=method, url=url, **kwargs)
  File "/usr/local/lib/python3.9/site-packages/requests/sessions.py", line 530, in request
    resp = self.send(prep, **send_kwargs)
  File "/usr/local/lib/python3.9/site-packages/requests/sessions.py", line 637, in send
    adapter = self.get_adapter(url=request.url)
  File "/usr/local/lib/python3.9/site-packages/requests/sessions.py", line 730, in get_adapter
    raise InvalidSchema("No connection adapters were found for {!r}".format(url))
requests.exceptions.InvalidSchema: No connection adapters were found for "('https://apod.nasa.gov/apod/ap200928.html', '200928')"
https://apod.nasa.gov/apod/ap210807.html
https://apod.nasa.gov/apod/ap211211.html
https://apod.nasa.gov/apod/ap220114.html
https://apod.nasa.gov/apod/ap211104.html
https://apod.nasa.gov/apod/ap200912.html
('https://apod.nasa.gov/apod/ap210330.html', '210330')
Traceback (most recent call last):
  File "/Users/jacobl/cron_jobs/scripts/soupv2.py", line 48, in find_image
    img_url = img_tag.get('src')
AttributeError: 'NoneType' object has no attribute 'get'

During handling of the above exception, another exception occurred:

Traceback (most recent call last):
  File "/Users/jacobl/cron_jobs/scripts/soupv2.py", line 103, in <module>
    main()
  File "/Users/jacobl/cron_jobs/scripts/soupv2.py", line 96, in main
    img_url,description = find_image(site)
  File "/Users/jacobl/cron_jobs/scripts/soupv2.py", line 53, in find_image
    find_image(site)
  File "/Users/jacobl/cron_jobs/scripts/soupv2.py", line 45, in find_image
    soup = BeautifulSoup(requests.get(site).text, 'html.parser')
  File "/usr/local/lib/python3.9/site-packages/requests/api.py", line 76, in get
    return request('get', url, params=params, **kwargs)
  File "/usr/local/lib/python3.9/site-packages/requests/api.py", line 61, in request
    return session.request(method=method, url=url, **kwargs)
  File "/usr/local/lib/python3.9/site-packages/requests/sessions.py", line 530, in request
    resp = self.send(prep, **send_kwargs)
  File "/usr/local/lib/python3.9/site-packages/requests/sessions.py", line 637, in send
    adapter = self.get_adapter(url=request.url)
  File "/usr/local/lib/python3.9/site-packages/requests/sessions.py", line 730, in get_adapter
    raise InvalidSchema("No connection adapters were found for {!r}".format(url))
requests.exceptions.InvalidSchema: No connection adapters were found for "('https://apod.nasa.gov/apod/ap210330.html', '210330')"
https://apod.nasa.gov/apod/ap210501.html
https://apod.nasa.gov/apod/ap200919.html
https://apod.nasa.gov/apod/ap210607.html
https://apod.nasa.gov/apod/ap201103.html
('https://apod.nasa.gov/apod/ap201207.html', '201207')
Traceback (most recent call last):
  File "/Users/jacobl/cron_jobs/scripts/soupv2.py", line 48, in find_image
    img_url = img_tag.get('src')
AttributeError: 'NoneType' object has no attribute 'get'

During handling of the above exception, another exception occurred:

Traceback (most recent call last):
  File "/Users/jacobl/cron_jobs/scripts/soupv2.py", line 103, in <module>
    main()
  File "/Users/jacobl/cron_jobs/scripts/soupv2.py", line 96, in main
    img_url,description = find_image(site)
  File "/Users/jacobl/cron_jobs/scripts/soupv2.py", line 53, in find_image
    find_image(site)
  File "/Users/jacobl/cron_jobs/scripts/soupv2.py", line 45, in find_image
    soup = BeautifulSoup(requests.get(site).text, 'html.parser')
  File "/usr/local/lib/python3.9/site-packages/requests/api.py", line 76, in get
    return request('get', url, params=params, **kwargs)
  File "/usr/local/lib/python3.9/site-packages/requests/api.py", line 61, in request
    return session.request(method=method, url=url, **kwargs)
  File "/usr/local/lib/python3.9/site-packages/requests/sessions.py", line 530, in request
    resp = self.send(prep, **send_kwargs)
  File "/usr/local/lib/python3.9/site-packages/requests/sessions.py", line 637, in send
    adapter = self.get_adapter(url=request.url)
  File "/usr/local/lib/python3.9/site-packages/requests/sessions.py", line 730, in get_adapter
    raise InvalidSchema("No connection adapters were found for {!r}".format(url))
requests.exceptions.InvalidSchema: No connection adapters were found for "('https://apod.nasa.gov/apod/ap201207.html', '201207')"
rm: /Users/jacobl/wallpaper/*_up.jpg: No such file or directory
https://apod.nasa.gov/apod/ap210508.html
https://apod.nasa.gov/apod/ap200913.html
https://apod.nasa.gov/apod/ap210111.html
('https://apod.nasa.gov/apod/ap210830.html', '210830')
Traceback (most recent call last):
  File "/Users/jacobl/cron_jobs/scripts/soupv2.py", line 48, in find_image
    img_url = img_tag.get('src')
AttributeError: 'NoneType' object has no attribute 'get'

During handling of the above exception, another exception occurred:

Traceback (most recent call last):
  File "/Users/jacobl/cron_jobs/scripts/soupv2.py", line 103, in <module>
    main()
  File "/Users/jacobl/cron_jobs/scripts/soupv2.py", line 96, in main
    img_url,description = find_image(site)
  File "/Users/jacobl/cron_jobs/scripts/soupv2.py", line 53, in find_image
    find_image(site)
  File "/Users/jacobl/cron_jobs/scripts/soupv2.py", line 45, in find_image
    soup = BeautifulSoup(requests.get(site).text, 'html.parser')
  File "/usr/local/lib/python3.9/site-packages/requests/api.py", line 76, in get
    return request('get', url, params=params, **kwargs)
  File "/usr/local/lib/python3.9/site-packages/requests/api.py", line 61, in request
    return session.request(method=method, url=url, **kwargs)
  File "/usr/local/lib/python3.9/site-packages/requests/sessions.py", line 530, in request
    resp = self.send(prep, **send_kwargs)
  File "/usr/local/lib/python3.9/site-packages/requests/sessions.py", line 637, in send
    adapter = self.get_adapter(url=request.url)
  File "/usr/local/lib/python3.9/site-packages/requests/sessions.py", line 730, in get_adapter
    raise InvalidSchema("No connection adapters were found for {!r}".format(url))
requests.exceptions.InvalidSchema: No connection adapters were found for "('https://apod.nasa.gov/apod/ap210830.html', '210830')"
https://apod.nasa.gov/apod/ap210728.html
https://apod.nasa.gov/apod/ap200919.html
https://apod.nasa.gov/apod/ap201223.html
https://apod.nasa.gov/apod/ap210112.html
https://apod.nasa.gov/apod/ap211027.html
https://apod.nasa.gov/apod/ap210211.html
https://apod.nasa.gov/apod/ap210301.html
https://apod.nasa.gov/apod/ap210204.html
https://apod.nasa.gov/apod/ap210303.html
https://apod.nasa.gov/apod/ap201011.html
https://apod.nasa.gov/apod/ap211218.html
https://apod.nasa.gov/apod/ap200921.html
https://apod.nasa.gov/apod/ap210220.html
https://apod.nasa.gov/apod/ap211107.html
https://apod.nasa.gov/apod/ap210212.html
https://apod.nasa.gov/apod/ap210622.html
https://apod.nasa.gov/apod/ap201103.html
('https://apod.nasa.gov/apod/ap210602.html', '210602')
Traceback (most recent call last):
  File "/Users/jacobl/cron_jobs/scripts/soupv2.py", line 48, in find_image
    img_url = img_tag.get('src')
AttributeError: 'NoneType' object has no attribute 'get'

During handling of the above exception, another exception occurred:

Traceback (most recent call last):
  File "/Users/jacobl/cron_jobs/scripts/soupv2.py", line 103, in <module>
    main()
  File "/Users/jacobl/cron_jobs/scripts/soupv2.py", line 96, in main
    img_url,description = find_image(site)
  File "/Users/jacobl/cron_jobs/scripts/soupv2.py", line 53, in find_image
    find_image(site)
  File "/Users/jacobl/cron_jobs/scripts/soupv2.py", line 45, in find_image
    soup = BeautifulSoup(requests.get(site).text, 'html.parser')
  File "/usr/local/lib/python3.9/site-packages/requests/api.py", line 76, in get
    return request('get', url, params=params, **kwargs)
  File "/usr/local/lib/python3.9/site-packages/requests/api.py", line 61, in request
    return session.request(method=method, url=url, **kwargs)
  File "/usr/local/lib/python3.9/site-packages/requests/sessions.py", line 530, in request
    resp = self.send(prep, **send_kwargs)
  File "/usr/local/lib/python3.9/site-packages/requests/sessions.py", line 637, in send
    adapter = self.get_adapter(url=request.url)
  File "/usr/local/lib/python3.9/site-packages/requests/sessions.py", line 730, in get_adapter
    raise InvalidSchema("No connection adapters were found for {!r}".format(url))
requests.exceptions.InvalidSchema: No connection adapters were found for "('https://apod.nasa.gov/apod/ap210602.html', '210602')"
https://apod.nasa.gov/apod/ap220110.html
('https://apod.nasa.gov/apod/ap201226.html', '201226')
Traceback (most recent call last):
  File "/Users/jacobl/cron_jobs/scripts/soupv2.py", line 48, in find_image
    img_url = img_tag.get('src')
AttributeError: 'NoneType' object has no attribute 'get'

During handling of the above exception, another exception occurred:

Traceback (most recent call last):
  File "/Users/jacobl/cron_jobs/scripts/soupv2.py", line 103, in <module>
    main()
  File "/Users/jacobl/cron_jobs/scripts/soupv2.py", line 96, in main
    img_url,description = find_image(site)
  File "/Users/jacobl/cron_jobs/scripts/soupv2.py", line 53, in find_image
    find_image(site)
  File "/Users/jacobl/cron_jobs/scripts/soupv2.py", line 45, in find_image
    soup = BeautifulSoup(requests.get(site).text, 'html.parser')
  File "/usr/local/lib/python3.9/site-packages/requests/api.py", line 76, in get
    return request('get', url, params=params, **kwargs)
  File "/usr/local/lib/python3.9/site-packages/requests/api.py", line 61, in request
    return session.request(method=method, url=url, **kwargs)
  File "/usr/local/lib/python3.9/site-packages/requests/sessions.py", line 530, in request
    resp = self.send(prep, **send_kwargs)
  File "/usr/local/lib/python3.9/site-packages/requests/sessions.py", line 637, in send
    adapter = self.get_adapter(url=request.url)
  File "/usr/local/lib/python3.9/site-packages/requests/sessions.py", line 730, in get_adapter
    raise InvalidSchema("No connection adapters were found for {!r}".format(url))
requests.exceptions.InvalidSchema: No connection adapters were found for "('https://apod.nasa.gov/apod/ap201226.html', '201226')"
rm: /Users/jacobl/wallpaper/*_up.jpg: No such file or directory
https://apod.nasa.gov/apod/ap210701.html
https://apod.nasa.gov/apod/ap211011.html
('https://apod.nasa.gov/apod/ap210127.html', '210127')
Traceback (most recent call last):
  File "/Users/jacobl/cron_jobs/scripts/soupv2.py", line 48, in find_image
    img_url = img_tag.get('src')
AttributeError: 'NoneType' object has no attribute 'get'

During handling of the above exception, another exception occurred:

Traceback (most recent call last):
  File "/Users/jacobl/cron_jobs/scripts/soupv2.py", line 103, in <module>
    main()
  File "/Users/jacobl/cron_jobs/scripts/soupv2.py", line 96, in main
    img_url,description = find_image(site)
  File "/Users/jacobl/cron_jobs/scripts/soupv2.py", line 53, in find_image
    find_image(site)
  File "/Users/jacobl/cron_jobs/scripts/soupv2.py", line 45, in find_image
    soup = BeautifulSoup(requests.get(site).text, 'html.parser')
  File "/usr/local/lib/python3.9/site-packages/requests/api.py", line 76, in get
    return request('get', url, params=params, **kwargs)
  File "/usr/local/lib/python3.9/site-packages/requests/api.py", line 61, in request
    return session.request(method=method, url=url, **kwargs)
  File "/usr/local/lib/python3.9/site-packages/requests/sessions.py", line 530, in request
    resp = self.send(prep, **send_kwargs)
  File "/usr/local/lib/python3.9/site-packages/requests/sessions.py", line 637, in send
    adapter = self.get_adapter(url=request.url)
  File "/usr/local/lib/python3.9/site-packages/requests/sessions.py", line 730, in get_adapter
    raise InvalidSchema("No connection adapters were found for {!r}".format(url))
requests.exceptions.InvalidSchema: No connection adapters were found for "('https://apod.nasa.gov/apod/ap210127.html', '210127')"
https://apod.nasa.gov/apod/ap211021.html
https://apod.nasa.gov/apod/ap201213.html
https://apod.nasa.gov/apod/ap210904.html
https://apod.nasa.gov/apod/ap210217.html
https://apod.nasa.gov/apod/ap210418.html
https://apod.nasa.gov/apod/ap210505.html
https://apod.nasa.gov/apod/ap210827.html
https://apod.nasa.gov/apod/ap210303.html
https://apod.nasa.gov/apod/ap211224.html
https://apod.nasa.gov/apod/ap210202.html
https://apod.nasa.gov/apod/ap210301.html
https://apod.nasa.gov/apod/ap210509.html
https://apod.nasa.gov/apod/ap201025.html
https://apod.nasa.gov/apod/ap210101.html
https://apod.nasa.gov/apod/ap220105.html
https://apod.nasa.gov/apod/ap210622.html
https://apod.nasa.gov/apod/ap211107.html
https://apod.nasa.gov/apod/ap210603.html
https://apod.nasa.gov/apod/ap210306.html
https://apod.nasa.gov/apod/ap220103.html
https://apod.nasa.gov/apod/ap210308.html
https://apod.nasa.gov/apod/ap210726.html
36:108: execution error: System Events got an error: Can’t get desktop 2. Invalid index. (-1719)
https://apod.nasa.gov/apod/ap211103.html
https://apod.nasa.gov/apod/ap210909.html
36:108: execution error: System Events got an error: Can’t get desktop 2. Invalid index. (-1719)
https://apod.nasa.gov/apod/ap201007.html
https://apod.nasa.gov/apod/ap210511.html
36:108: execution error: System Events got an error: Can’t get desktop 2. Invalid index. (-1719)
https://apod.nasa.gov/apod/ap201124.html
https://apod.nasa.gov/apod/ap210609.html
https://apod.nasa.gov/apod/ap210315.html
('https://apod.nasa.gov/apod/ap211119.html', '211119')
Traceback (most recent call last):
  File "/Users/jacobl/cron_jobs/scripts/soupv2.py", line 48, in find_image
    img_url = img_tag.get('src')
AttributeError: 'NoneType' object has no attribute 'get'

During handling of the above exception, another exception occurred:

Traceback (most recent call last):
  File "/Users/jacobl/cron_jobs/scripts/soupv2.py", line 103, in <module>
    main()
  File "/Users/jacobl/cron_jobs/scripts/soupv2.py", line 96, in main
    img_url,description = find_image(site)
  File "/Users/jacobl/cron_jobs/scripts/soupv2.py", line 53, in find_image
    find_image(site)
  File "/Users/jacobl/cron_jobs/scripts/soupv2.py", line 45, in find_image
    soup = BeautifulSoup(requests.get(site).text, 'html.parser')
  File "/usr/local/lib/python3.9/site-packages/requests/api.py", line 76, in get
    return request('get', url, params=params, **kwargs)
  File "/usr/local/lib/python3.9/site-packages/requests/api.py", line 61, in request
    return session.request(method=method, url=url, **kwargs)
  File "/usr/local/lib/python3.9/site-packages/requests/sessions.py", line 530, in request
    resp = self.send(prep, **send_kwargs)
  File "/usr/local/lib/python3.9/site-packages/requests/sessions.py", line 637, in send
    adapter = self.get_adapter(url=request.url)
  File "/usr/local/lib/python3.9/site-packages/requests/sessions.py", line 730, in get_adapter
    raise InvalidSchema("No connection adapters were found for {!r}".format(url))
requests.exceptions.InvalidSchema: No connection adapters were found for "('https://apod.nasa.gov/apod/ap211119.html', '211119')"
rm: /Users/jacobl/wallpaper/*_up.jpg: No such file or directory
36:108: execution error: System Events got an error: Can’t get desktop 2. Invalid index. (-1719)
https://apod.nasa.gov/apod/ap210609.html
https://apod.nasa.gov/apod/ap210403.html
36:108: execution error: System Events got an error: Can’t get desktop 2. Invalid index. (-1719)
https://apod.nasa.gov/apod/ap201228.html
https://apod.nasa.gov/apod/ap211101.html
36:108: execution error: System Events got an error: Can’t get desktop 2. Invalid index. (-1719)
https://apod.nasa.gov/apod/ap210511.html
https://apod.nasa.gov/apod/ap201008.html
36:108: execution error: System Events got an error: Can’t get desktop 2. Invalid index. (-1719)
https://apod.nasa.gov/apod/ap201016.html
https://apod.nasa.gov/apod/ap210202.html
36:108: execution error: System Events got an error: Can’t get desktop 2. Invalid index. (-1719)
https://apod.nasa.gov/apod/ap210625.html
https://apod.nasa.gov/apod/ap210429.html
36:108: execution error: System Events got an error: Can’t get desktop 2. Invalid index. (-1719)
https://apod.nasa.gov/apod/ap201014.html
https://apod.nasa.gov/apod/ap201225.html
36:108: execution error: System Events got an error: Can’t get desktop 2. Invalid index. (-1719)
https://apod.nasa.gov/apod/ap201202.html
https://apod.nasa.gov/apod/ap200920.html
https://apod.nasa.gov/apod/ap210825.html
('https://apod.nasa.gov/apod/ap210627.html', '210627')
Traceback (most recent call last):
  File "/Users/jacobl/cron_jobs/scripts/soupv2.py", line 48, in find_image
    img_url = img_tag.get('src')
AttributeError: 'NoneType' object has no attribute 'get'

During handling of the above exception, another exception occurred:

Traceback (most recent call last):
  File "/Users/jacobl/cron_jobs/scripts/soupv2.py", line 103, in <module>
    main()
  File "/Users/jacobl/cron_jobs/scripts/soupv2.py", line 96, in main
    img_url,description = find_image(site)
  File "/Users/jacobl/cron_jobs/scripts/soupv2.py", line 53, in find_image
    find_image(site)
  File "/Users/jacobl/cron_jobs/scripts/soupv2.py", line 45, in find_image
    soup = BeautifulSoup(requests.get(site).text, 'html.parser')
  File "/usr/local/lib/python3.9/site-packages/requests/api.py", line 76, in get
    return request('get', url, params=params, **kwargs)
  File "/usr/local/lib/python3.9/site-packages/requests/api.py", line 61, in request
    return session.request(method=method, url=url, **kwargs)
  File "/usr/local/lib/python3.9/site-packages/requests/sessions.py", line 530, in request
    resp = self.send(prep, **send_kwargs)
  File "/usr/local/lib/python3.9/site-packages/requests/sessions.py", line 637, in send
    adapter = self.get_adapter(url=request.url)
  File "/usr/local/lib/python3.9/site-packages/requests/sessions.py", line 730, in get_adapter
    raise InvalidSchema("No connection adapters were found for {!r}".format(url))
requests.exceptions.InvalidSchema: No connection adapters were found for "('https://apod.nasa.gov/apod/ap210627.html', '210627')"
rm: /Users/jacobl/wallpaper/*_up.jpg: No such file or directory
36:107: execution error: System Events got an error: Can’t get desktop 1. Invalid index. (-1719)
36:108: execution error: System Events got an error: Can’t get desktop 2. Invalid index. (-1719)
https://apod.nasa.gov/apod/ap200913.html
https://apod.nasa.gov/apod/ap211217.html
36:107: execution error: System Events got an error: Can’t get desktop 1. Invalid index. (-1719)
https://apod.nasa.gov/apod/ap210809.html
https://apod.nasa.gov/apod/ap211217.html
https://apod.nasa.gov/apod/ap211106.html
https://apod.nasa.gov/apod/ap210513.html
https://apod.nasa.gov/apod/ap211117.html
https://apod.nasa.gov/apod/ap211207.html
https://apod.nasa.gov/apod/ap210411.html
('https://apod.nasa.gov/apod/ap210521.html', '210521')
Traceback (most recent call last):
  File "/Users/jacobl/cron_jobs/scripts/soupv2.py", line 48, in find_image
    img_url = img_tag.get('src')
AttributeError: 'NoneType' object has no attribute 'get'

During handling of the above exception, another exception occurred:

Traceback (most recent call last):
  File "/Users/jacobl/cron_jobs/scripts/soupv2.py", line 103, in <module>
    main()
  File "/Users/jacobl/cron_jobs/scripts/soupv2.py", line 96, in main
    img_url,description = find_image(site)
  File "/Users/jacobl/cron_jobs/scripts/soupv2.py", line 53, in find_image
    find_image(site)
  File "/Users/jacobl/cron_jobs/scripts/soupv2.py", line 45, in find_image
    soup = BeautifulSoup(requests.get(site).text, 'html.parser')
  File "/usr/local/lib/python3.9/site-packages/requests/api.py", line 76, in get
    return request('get', url, params=params, **kwargs)
  File "/usr/local/lib/python3.9/site-packages/requests/api.py", line 61, in request
    return session.request(method=method, url=url, **kwargs)
  File "/usr/local/lib/python3.9/site-packages/requests/sessions.py", line 530, in request
    resp = self.send(prep, **send_kwargs)
  File "/usr/local/lib/python3.9/site-packages/requests/sessions.py", line 637, in send
    adapter = self.get_adapter(url=request.url)
  File "/usr/local/lib/python3.9/site-packages/requests/sessions.py", line 730, in get_adapter
    raise InvalidSchema("No connection adapters were found for {!r}".format(url))
requests.exceptions.InvalidSchema: No connection adapters were found for "('https://apod.nasa.gov/apod/ap210521.html', '210521')"
